Workbook

Sheet state_to_language
A1: STATE NAME | B1: LANGUAGE | C1: ABBREVIATION
A2: BIHAR | B2: Hindi | C2: Hin
A3: CHHATTISGARH | B3: Hindi | C3: Hin
A4: HARYANA | B4: Hindi | C4: Hin
A5: HIMACHAL PRADESH | B5: Hindi | C5: Hin
A6: JHARKHAND | B6: Hindi | C6: Hin
A7: KARNATAKA | B7: Kannada | C7: Kan
A8: MADHYA PRADESH | B8: Hindi | C8: Hin
A9: MAHARASHTRA | B9: Marathi | C9: Mar
A10: ODISHA | B10: Odia | C10: Odi
A11: PUNJAB | B11: Punjabi | C11: Pun
A12: RAJASTHAN | B12: Hindi | C12: Hin
... A16: WEST BENGAL | B16: Bengali | C16: Ben

Sheet grid_box_state_language
A1: lat_cent | B1: lon_cent | C1: grid_id | D1: STATE_UT | E1: Language | F1: (note: this is all grids/states from Alex's code, we should exclud eareas we're not disseminating to)
A2: 24 | B2: 88 | C2: 168 | D2: BIHAR | E2: =VLOOKUP(D2, state_to_language!$A:$C, 3, FALSE ) -> Hin
A3: 24 | B3: 88 | C3: 168 | D3: JHARKHAND | E3: =VLOOKUP(D3, state_to_language!$A:$C, 3, FALSE ) -> Hin
A4: 24 | B4: 88 | C4: 168 | D4: WEST BENGAL | E4: =VLOOKUP(D4, state_to_language!$A:$C, 3, FALSE ) -> Ben
A5: 22 | B5: 88 | C5: 169 | D5: WEST BENGAL | E5: =VLOOKUP(D5, state_to_language!$A:$C, 3, FALSE ) -> Ben
A6: 22 | B6: 88 | C6: 169 | D6: ODISHA | E6: =VLOOKUP(D6, state_to_language!$A:$C, 3, FALSE ) -> Odi
A7: 24 | B7: 86 | C7: 152 | D7: BIHAR | E7: =VLOOKUP(D7, state_to_language!$A:$C, 3, FALSE ) -> Hin
A8: 24 | B8: 86 | C8: 152 | D8: JHARKHAND | E8: =VLOOKUP(D8, state_to_language!$A:$C, 3, FALSE ) -> Hin
A9: 24 | B9: 86 | C9: 152 | D9: WEST BENGAL | E9: =VLOOKUP(D9, state_to_language!$A:$C, 3, FALSE ) -> Ben
A10: 22 | B10: 86 | C10: 153 | D10: JHARKHAND | E10: =VLOOKUP(D10, state_to_language!$A:$C, 3, FALSE ) -> Hin
A11: 22 | B11: 86 | C11: 153 | D11: ODISHA | E11: =VLOOKUP(D11, state_to_language!$A:$C, 3, FALSE ) -> Odi
A12: 26 | B12: 84 | C12: 135 | D12: BIHAR | E12: =VLOOKUP(D12, state_to_language!$A:$C, 3, FALSE ) -> Hin
A13: 26 | B13: 84 | C13: 135 | D13: UTTAR PRADESH | E13: =VLOOKUP(D13, state_to_language!$A:$C, 3, FALSE ) -> Hin
... A78: 18 | B78: 76 | C78: 75 | D78: MAHARASHTRA | E78: =VLOOKUP(D78, state_to_language!$A:$C, 3, FALSE ) -> Mar

Sheet grid_box
A1: lat | B1: lon | C1: gridbox | D1: grid_id | E1: state | F1: state_code | G1: language | H1: abbreviation | I1: campaign
A2: =IFERROR(__xludf.DUMMYFUNCTION("TRIM(INDEX(SPLIT(C2,"",""),1))"),"20") -> 20 | B2: =IFERROR(__xludf.DUMMYFUNCTION("TRIM(INDEX(SPLIT(C2,"",""),2))"),"82") -> 82 | C2: 20,82 | D2: 10 | E2: ODISHA | F2: 21 | G2: Odia | H2: Odi | I2: 10_ODISHA_Odia
A3: =IFERROR(__xludf.DUMMYFUNCTION("TRIM(INDEX(SPLIT(C3,"",""),1))"),"20") -> 20 | B3: =IFERROR(__xludf.DUMMYFUNCTION("TRIM(INDEX(SPLIT(C3,"",""),2))"),"82") -> 82 | C3: 20,82 | D3: 10 | E3: CHHATTISGARH | F3: 22 | G3: Hindi | H3: Hin | I3: 10_CHHATTISGARH_Hindi
A4: =IFERROR(__xludf.DUMMYFUNCTION("TRIM(INDEX(SPLIT(C4,"",""),1))"),"20") -> 20 | B4: =IFERROR(__xludf.DUMMYFUNCTION("TRIM(INDEX(SPLIT(C4,"",""),2))"),"84") -> 84 | C4: 20,84 | D4: 11 | E4: ODISHA | F4: 21 | G4: Odia | H4: Odi | I4: 11_ODISHA_Odia
A5: =IFERROR(__xludf.DUMMYFUNCTION("TRIM(INDEX(SPLIT(C5,"",""),1))"),"22") -> 22 | B5: =IFERROR(__xludf.DUMMYFUNCTION("TRIM(INDEX(SPLIT(C5,"",""),2))"),"76") -> 76 | C5: 22,76 | D5: 14 | E5: MAHARASHTRA | F5: 27 | G5: Marathi | H5: Mar | I5: 14_MAHARASHTRA_Marathi
A6: =IFERROR(__xludf.DUMMYFUNCTION("TRIM(INDEX(SPLIT(C6,"",""),1))"),"22") -> 22 | B6: =IFERROR(__xludf.DUMMYFUNCTION("TRIM(INDEX(SPLIT(C6,"",""),2))"),"76") -> 76 | C6: 22,76 | D6: 14 | E6: MADHYA PRADESH | F6: 23 | G6: Hindi | H6: Hin | I6: 14_MADHYA PRADESH_Hindi
A7: =IFERROR(__xludf.DUMMYFUNCTION("TRIM(INDEX(SPLIT(C7,"",""),1))"),"22") -> 22 | B7: =IFERROR(__xludf.DUMMYFUNCTION("TRIM(INDEX(SPLIT(C7,"",""),2))"),"78") -> 78 | C7: 22,78 | D7: 15 | E7: MADHYA PRADESH | F7: 23 | G7: Hindi | H7: Hin | I7: 15_MADHYA PRADESH_Hindi
A8: =IFERROR(__xludf.DUMMYFUNCTION("TRIM(INDEX(SPLIT(C8,"",""),1))"),"22") -> 22 | B8: =IFERROR(__xludf.DUMMYFUNCTION("TRIM(INDEX(SPLIT(C8,"",""),2))"),"78") -> 78 | C8: 22,78 | D8: 15 | E8: MAHARASHTRA | F8: 27 | G8: Marathi | H8: Mar | I8: 15_MAHARASHTRA_Marathi
A9: =IFERROR(__xludf.DUMMYFUNCTION("TRIM(INDEX(SPLIT(C9,"",""),1))"),"22") -> 22 | B9: =IFERROR(__xludf.DUMMYFUNCTION("TRIM(INDEX(SPLIT(C9,"",""),2))"),"80") -> 80 | C9: 22,80 | D9: 16 | E9: CHHATTISGARH | F9: 22 | G9: Hindi | H9: Hin | I9: 16_CHHATTISGARH_Hindi
A10: =IFERROR(__xludf.DUMMYFUNCTION("TRIM(INDEX(SPLIT(C10,"",""),1))"),"22") -> 22 | B10: =IFERROR(__xludf.DUMMYFUNCTION("TRIM(INDEX(SPLIT(C10,"",""),2))"),"80") -> 80 | C10: 22,80 | D10: 16 | E10: MAHARASHTRA | F10: 27 | G10: Marathi | H10: Mar | I10: 16_MAHARASHTRA_Marathi
A11: =IFERROR(__xludf.DUMMYFUNCTION("TRIM(INDEX(SPLIT(C11,"",""),1))"),"22") -> 22 | B11: =IFERROR(__xludf.DUMMYFUNCTION("TRIM(INDEX(SPLIT(C11,"",""),2))"),"80") -> 80 | C11: 22,80 | D11: 16 | E11: MADHYA PRADESH | F11: 23 | G11: Hindi | H11: Hin | I11: 16_MADHYA PRADESH_Hindi
A12: =IFERROR(__xludf.DUMMYFUNCTION("TRIM(INDEX(SPLIT(C12,"",""),1))"),"22") -> 22 | B12: =IFERROR(__xludf.DUMMYFUNCTION("TRIM(INDEX(SPLIT(C12,"",""),2))"),"82") -> 82 | C12: 22,82 | D12: 17 | E12: ODISHA | F12: 21 | G12: Odia | H12: Odi | I12: 17_ODISHA_Odia
A13: =IFERROR(__xludf.DUMMYFUNCTION("TRIM(INDEX(SPLIT(C13,"",""),1))"),"22") -> 22 | B13: =IFERROR(__xludf.DUMMYFUNCTION("TRIM(INDEX(SPLIT(C13,"",""),2))"),"82") -> 82 | C13: 22,82 | D13: 17 | E13: MADHYA PRADESH | F13: 23 | G13: Hindi | H13: Hin | I13: 17_MADHYA PRADESH_Hindi
A14: =IFERROR(__xludf.DUMMYFUNCTION("TRIM(INDEX(SPLIT(C14,"",""),1))"),"22") -> 22 | B14: =IFERROR(__xludf.DUMMYFUNCTION("TRIM(INDEX(SPLIT(C14,"",""),2))"),"82") -> 82 | C14: 22,82 | D14: 17 | E14: CHHATTISGARH | F14: 22 | G14: Hindi | H14: Hin | I14: 17_CHHATTISGARH_Hindi
A15: =IFERROR(__xludf.DUMMYFUNCTION("TRIM(INDEX(SPLIT(C15,"",""),1))"),"22") -> 22 | B15: =IFERROR(__xludf.DUMMYFUNCTION("TRIM(INDEX(SPLIT(C15,"",""),2))"),"84") -> 84 | C15: 22,84 | D15: 18 | E15: JHARKHAND | F15: 20 | G15: Hindi | H15: Hin | I15: 18_JHARKHAND_Hindi
A16: =IFERROR(__xludf.DUMMYFUNCTION("TRIM(INDEX(SPLIT(C16,"",""),1))"),"22") -> 22 | B16: =IFERROR(__xludf.DUMMYFUNCTION("TRIM(INDEX(SPLIT(C16,"",""),2))"),"84") -> 84 | C16: 22,84 | D16: 18 | E16: ODISHA | F16: 21 | G16: Odia | H16: Odi | I16: 18_ODISHA_Odia
A17: =IFERROR(__xludf.DUMMYFUNCTION("TRIM(INDEX(SPLIT(C17,"",""),1))"),"22") -> 22 | B17: =IFERROR(__xludf.DUMMYFUNCTION("TRIM(INDEX(SPLIT(C17,"",""),2))"),"84") -> 84 | C17: 22,84 | D17: 18 | E17: CHHATTISGARH | F17: 22 | G17: Hindi | H17: Hin | I17: 18_CHHATTISGARH_Hindi
A18: =IFERROR(__xludf.DUMMYFUNCTION("TRIM(INDEX(SPLIT(C18,"",""),1))"),"22") -> 22 | B18: =IFERROR(__xludf.DUMMYFUNCTION("TRIM(INDEX(SPLIT(C18,"",""),2))"),"86") -> 86 | C18: 22,86 | D18: 19 | E18: JHARKHAND | F18: 20 | G18: Hindi | H18: Hin | I18: 19_JHARKHAND_Hindi
A19: =IFERROR(__xludf.DUMMYFUNCTION("TRIM(INDEX(SPLIT(C19,"",""),1))"),"22") -> 22 | B19: =IFERROR(__xludf.DUMMYFUNCTION("TRIM(INDEX(SPLIT(C19,"",""),2))"),"86") -> 86 | C19: 22,86 | D19: 19 | E19: WEST BENGAL | F19: 19 | G19: Bengali | H19: Ben | I19: 19_WEST BENGAL_Bengali
A20: =IFERROR(__xludf.DUMMYFUNCTION("TRIM(INDEX(SPLIT(C20,"",""),1))"),"22") -> 22 | B20: =IFERROR(__xludf.DUMMYFUNCTION("TRIM(INDEX(SPLIT(C20,"",""),2))"),"86") -> 86 | C20: 22,86 | D20: 19 | E20: ODISHA | F20: 21 | G20: Odia | H20: Odi | I20: 19_ODISHA_Odia
A21: =IFERROR(__xludf.DUMMYFUNCTION("TRIM(INDEX(SPLIT(C21,"",""),1))"),"22") -> 22 | B21: =IFERROR(__xludf.DUMMYFUNCTION("TRIM(INDEX(SPLIT(C21,"",""),2))"),"88") -> 88 | C21: 22,88 | D21: 20 | E21: WEST BENGAL | F21: 19 | G21: Bengali | H21: Ben | I21: 20_WEST BENGAL_Bengali
A22: =IFERROR(__xludf.DUMMYFUNCTION("TRIM(INDEX(SPLIT(C22,"",""),1))"),"22") -> 22 | B22: =IFERROR(__xludf.DUMMYFUNCTION("TRIM(INDEX(SPLIT(C22,"",""),2))"),"88") -> 88 | C22: 22,88 | D22: 20 | E22: ODISHA | F22: 21 | G22: Odia | H22: Odi | I22: 20_ODISHA_Odia
A23: =IFERROR(__xludf.DUMMYFUNCTION("TRIM(INDEX(SPLIT(C23,"",""),1))"),"24") -> 24 | B23: =IFERROR(__xludf.DUMMYFUNCTION("TRIM(INDEX(SPLIT(C23,"",""),2))"),"76") -> 76 | C23: 24,76 | D23: 23 | E23: MADHYA PRADESH | F23: 23 | G23: Hindi | H23: Hin | I23: 23_MADHYA PRADESH_Hindi
A24: =IFERROR(__xludf.DUMMYFUNCTION("TRIM(INDEX(SPLIT(C24,"",""),1))"),"24") -> 24 | B24: =IFERROR(__xludf.DUMMYFUNCTION("TRIM(INDEX(SPLIT(C24,"",""),2))"),"76") -> 76 | C24: 24,76 | D24: 23 | E24: RAJASTHAN | F24: 8 | G24: Hindi | H24: Hin | I24: 23_RAJASTHAN_Hindi
A25: =IFERROR(__xludf.DUMMYFUNCTION("TRIM(INDEX(SPLIT(C25,"",""),1))"),"24") -> 24 | B25: =IFERROR(__xludf.DUMMYFUNCTION("TRIM(INDEX(SPLIT(C25,"",""),2))"),"78") -> 78 | C25: 24,78 | D25: 24 | E25: MADHYA PRADESH | F25: 23 | G25: Hindi | H25: Hin | I25: 24_MADHYA PRADESH_Hindi
A26: =IFERROR(__xludf.DUMMYFUNCTION("TRIM(INDEX(SPLIT(C26,"",""),1))"),"24") -> 24 | B26: =IFERROR(__xludf.DUMMYFUNCTION("TRIM(INDEX(SPLIT(C26,"",""),2))"),"78") -> 78 | C26: 24,78 | D26: 24 | E26: UTTAR PRADESH | F26: 9 | G26: Hindi | H26: Hin | I26: 24_UTTAR PRADESH_Hindi
A27: =IFERROR(__xludf.DUMMYFUNCTION("TRIM(INDEX(SPLIT(C27,"",""),1))"),"24") -> 24 | B27: =IFERROR(__xludf.DUMMYFUNCTION("TRIM(INDEX(SPLIT(C27,"",""),2))"),"80") -> 80 | C27: 24,80 | D27: 25 | E27: UTTAR PRADESH | F27: 9 | G27: Hindi | H27: Hin | I27: 25_UTTAR PRADESH_Hindi
A28: =IFERROR(__xludf.DUMMYFUNCTION("TRIM(INDEX(SPLIT(C28,"",""),1))"),"24") -> 24 | B28: =IFERROR(__xludf.DUMMYFUNCTION("TRIM(INDEX(SPLIT(C28,"",""),2))"),"80") -> 80 | C28: 24,80 | D28: 25 | E28: MADHYA PRADESH | F28: 23 | G28: Hindi | H28: Hin | I28: 25_MADHYA PRADESH_Hindi
A29: =IFERROR(__xludf.DUMMYFUNCTION("TRIM(INDEX(SPLIT(C29,"",""),1))"),"24") -> 24 | B29: =IFERROR(__xludf.DUMMYFUNCTION("TRIM(INDEX(SPLIT(C29,"",""),2))"),"82") -> 82 | C29: 24,82 | D29: 26 | E29: CHHATTISGARH | F29: 22 | G29: Hindi | H29: Hin | I29: 26_CHHATTISGARH_Hindi
A30: =IFERROR(__xludf.DUMMYFUNCTION("TRIM(INDEX(SPLIT(C30,"",""),1))"),"24") -> 24 | B30: =IFERROR(__xludf.DUMMYFUNCTION("TRIM(INDEX(SPLIT(C30,"",""),2))"),"82") -> 82 | C30: 24,82 | D30: 26 | E30: UTTAR PRADESH | F30: 9 | G30: Hindi | H30: Hin | I30: 26_UTTAR PRADESH_Hindi
A31: =IFERROR(__xludf.DUMMYFUNCTION("TRIM(INDEX(SPLIT(C31,"",""),1))"),"24") -> 24 | B31: =IFERROR(__xludf.DUMMYFUNCTION("TRIM(INDEX(SPLIT(C31,"",""),2))"),"82") -> 82 | C31: 24,82 | D31: 26 | E31: MADHYA PRADESH | F31: 23 | G31: Hindi | H31: Hin | I31: 26_MADHYA PRADESH_Hindi
A32: =IFERROR(__xludf.DUMMYFUNCTION("TRIM(INDEX(SPLIT(C32,"",""),1))"),"24") -> 24 | B32: =IFERROR(__xludf.DUMMYFUNCTION("TRIM(INDEX(SPLIT(C32,"",""),2))"),"84") -> 84 | C32: 24,84 | D32: 27 | E32: UTTAR PRADESH | F32: 9 | G32: Hindi | H32: Hin | I32: 27_UTTAR PRADESH_Hindi
A33: =IFERROR(__xludf.DUMMYFUNCTION("TRIM(INDEX(SPLIT(C33,"",""),1))"),"24") -> 24 | B33: =IFERROR(__xludf.DUMMYFUNCTION("TRIM(INDEX(SPLIT(C33,"",""),2))"),"84") -> 84 | C33: 24,84 | D33: 27 | E33: BIHAR | F33: 10 | G33: Hindi | H33: Hin | I33: 27_BIHAR_Hindi
A34: =IFERROR(__xludf.DUMMYFUNCTION("TRIM(INDEX(SPLIT(C34,"",""),1))"),"24") -> 24 | B34: =IFERROR(__xludf.DUMMYFUNCTION("TRIM(INDEX(SPLIT(C34,"",""),2))"),"84") -> 84 | C34: 24,84 | D34: 27 | E34: CHHATTISGARH | F34: 22 | G34: Hindi | H34: Hin | I34: 27_CHHATTISGARH_Hindi
A35: =IFERROR(__xludf.DUMMYFUNCTION("TRIM(INDEX(SPLIT(C35,"",""),1))"),"24") -> 24 | B35: =IFERROR(__xludf.DUMMYFUNCTION("TRIM(INDEX(SPLIT(C35,"",""),2))"),"84") -> 84 | C35: 24,84 | D35: 27 | E35: JHARKHAND | F35: 20 | G35: Hindi | H35: Hin | I35: 27_JHARKHAND_Hindi
A36: =IFERROR(__xludf.DUMMYFUNCTION("TRIM(INDEX(SPLIT(C36,"",""),1))"),"24") -> 24 | B36: =IFERROR(__xludf.DUMMYFUNCTION("TRIM(INDEX(SPLIT(C36,"",""),2))"),"86") -> 86 | C36: 24,86 | D36: 28 | E36: BIHAR | F36: 10 | G36: Hindi | H36: Hin | I36: 28_BIHAR_Hindi
A37: =IFERROR(__xludf.DUMMYFUNCTION("TRIM(INDEX(SPLIT(C37,"",""),1))"),"24") -> 24 | B37: =IFERROR(__xludf.DUMMYFUNCTION("TRIM(INDEX(SPLIT(C37,"",""),2))"),"86") -> 86 | C37: 24,86 | D37: 28 | E37: WEST BENGAL | F37: 19 | G37: Bengali | H37: Ben | I37: 28_WEST BENGAL_Bengali
A38: =IFERROR(__xludf.DUMMYFUNCTION("TRIM(INDEX(SPLIT(C38,"",""),1))"),"24") -> 24 | B38: =IFERROR(__xludf.DUMMYFUNCTION("TRIM(INDEX(SPLIT(C38,"",""),2))"),"86") -> 86 | C38: 24,86 | D38: 28 | E38: JHARKHAND | F38: 20 | G38: Hindi | H38: Hin | I38: 28_JHARKHAND_Hindi
A39: =IFERROR(__xludf.DUMMYFUNCTION("TRIM(INDEX(SPLIT(C39,"",""),1))"),"24") -> 24 | B39: =IFERROR(__xludf.DUMMYFUNCTION("TRIM(INDEX(SPLIT(C39,"",""),2))"),"88") -> 88 | C39: 24,88 | D39: 29 | E39: JHARKHAND | F39: 20 | G39: Hindi | H39: Hin | I39: 29_JHARKHAND_Hindi
A40: =IFERROR(__xludf.DUMMYFUNCTION("TRIM(INDEX(SPLIT(C40,"",""),1))"),"24") -> 24 | B40: =IFERROR(__xludf.DUMMYFUNCTION("TRIM(INDEX(SPLIT(C40,"",""),2))"),"88") -> 88 | C40: 24,88 | D40: 29 | E40: WEST BENGAL | F40: 19 | G40: Bengali | H40: Ben | I40: 29_WEST BENGAL_Bengali
...

Sheet template_abbreviation
A1: message_template | B1: abbreviation
A2: Promotional Message 1 | B2: PM1
A3: Promotional Message 2 | B3: PM2
A4: Early Season Forecast 1 | B4: ES1
A5: Early Season Forecast 2 | B5: ES2
A6: Late Season Forecast 1 | B6: LS1
A7: Late Season Forecast 2 | B7: LS2
A8: Late Season Forecast 3 | B8: LS3
A9: Late Season Forecast 4 | B9: LS4
A10: Onset Confirmation Forecast 1 | B10: OC1
A11: Onset Confirmation Forecast 2 | B11: OC2
A12: Dry Spell Forecast 1 | B12: DS1
A13: Dry Spell Forecast 2 | B13: DS2

Sheet language_abbreviations
A1: Language | B1: Abbreviation
A2: English | B2: =LEFT(A2,3) -> Eng
A3: Hindi | B3: =LEFT(A3,3) -> Hin
A4: Marathi | B4: =LEFT(A4,3) -> Mar
A5: Odia | B5: =LEFT(A5,3) -> Odi
A6: Bengali | B6: =LEFT(A6,3) -> Ben
A7: Telugu | B7: =LEFT(A7,3) -> Tel
A8: Kannada | B8: =LEFT(A8,3) -> Kan
A9: Punjabi | B9: =LEFT(A9,3) -> Pun

Sheet months
A1: Eng | B1: Hin | C1: Mar | D1: Odi | E1: Ben | F1: Tel | G1: Kan | H1: Pun
A2: May | B2: मई | C2: मे | D2: ମଇ | E2: মে | F2: మే | G2: ಮೇ | H2: ਮਈ
A3: June | B3: जून | C3: जून | D3: ଜୁନ୍ | E3: জুন | F3: జూన్ | G3: ಜೂನ್ | H3: ਜੂਨ
A4: July | B4: जुलाई | C4: जुलै | D4: ଜୁଲାଇ | E4: জুলাই | F4: జూలై | G4: ಜುಲೈ | H4: ਜੁਲਾਈ
A5: August | B5: अगस्त | C5: ऑगस्ट | D5: ଅଗଷ୍ଟ | E5: আগস্ট | F5: ఆగస్టు | G5: ಆಗಸ್ಟ್ | H5: ਅਗਸਤ

Sheet qualitative
A1: Eng | B1: Hin | C1: Mar | D1: Odi | E1: Ben | F1: Tel | G1: Kan | H1: Pun
A2: very low | B2: बहुत कम | C2: खूप कमी | D2: ଅତ୍ୟଧିକ କମ | E2: খুব কম | F2: చాలా తక్కువ | G2: ತುಂಬಾ ಕಡಿಮೆ | H2: ਬਹੁਤ ਘੱਟ
A3: low | B3: कम | C3: कमी | D3: କମ | E3: কম | F3: తక్కువ | G3: ಕಡಿಮೆ | H3: ਘੱਟ
A4: moderate | B4: मध्यम | C4: मध्यम | D4: ମଧ୍ୟମ | E4: মাঝারি | F4: మధ్యస్థ | G4: ಮಧ್ಯಮ | H4: ਮਧਿਆਮ
A5: high | B5: अधिक | C5: जास्त | D5: ଅଧିକ | E5: বেশি | F5: ఎక్కువ | G5: ಹೆಚ್ಚು | H5: ਉੱਚੀ
A6: very high | B6: बहुत अधिक | C6: खूप जास्त | D6: ଅତ୍ୟଧିକ ଅଧିକ | E6: খুব বেশি | F6: చాలా ఎక్కువ | G6: ತುಂಬಾ ಹೆಚ್ಚು | H6: ਬਹੁਤ ਉੱਚੀ

Sheet NM
B1: hin | C1: mar | D1: odi | E1: ben | F1: tel | G1: kan | H1: pun
A2: no message this week (this is a placeholder fort the version of this message that will eventually be written)

Sheet PM1
A1: eng | B1: hin | C1: mar | D1: odi | E1: ben | F1: tel | G1: kan | H1: pun
A2: Information for farmers: The Ministry of Agriculture will send SMS upDates from this number about when the rainy season is likely to arrive in your locality this year. The arrival of the rainy season does not just mean the first rainfall; it means the start of continuous rains. Please share this with other farmers in your locality. Accurate estimates will be shared when available. Please note: Real rainy season conditions may vary from the estimate. <Attribution to be hyperlinked here> | B2: किसानों के लिए जानकारी: कृषि मंत्रालय इस साल आपके इलाके में बरसात का मौसम आने की संभावना के बारे में इस नंबर से SMS अपडेट भेजेगा। बारिश का मौसम आने का मतलब बस पहली बारिश नहीं है, इसका मतलब है लगातार बारिश की शुरुआत| कृपया इसे अपने इलाके के अन्य किसानों के साथ साझा करें। सटीक अनुमान उपलब्ध होने पर भेजे जाएंगे। कृपया ध्यान दें: असली बारिश का मौसम की स्थिति अनुमान से अलग हो सक्ती है। <Attribution to be hyperlinked here> | C2: शेतकऱ्यांसाठी माहिती – या वर्षी तुमच्या भागात पावसाळा कधी सुरू होईल, यासंदर्भात कृषी मंत्रालय या क्रमांकावरून SMS पाठवेल. पावसाळा सुरू होणे म्हणजे केवळ पहिल्या सरी नव्हे, तर सलग पावसाची सुरुवात होय. कृपया ही माहिती आपल्या भागातील इतर शेतकऱ्यांपर्यंत पोहोचवा. अचूक अंदाज उपलब्ध होताच शेअर केले जातील. कृपया लक्षात ठेवा: पावसाळ्याची खरी परिस्थिती अंदाजापेक्षा वेगळी असू शकते. <Attribution to be hyperlinked here> | D2: କୃଷକମାନଙ୍କ ପାଇଁ ସୂଚନା: ଏହି ବର୍ଷ ଆପଣଙ୍କ ଅଞ୍ଚଳରେ ବର୍ଷା ଋତୁ କେବେ ଆସିବ ସେ ବିଷୟରେ କୃଷି ମନ୍ତ୍ରଣାଳୟ ଏହି ନମ୍ବରରୁ SMS ଅପଡେଟ୍ ପଠାଇବ। ବର୍ଷା ଋତୁର ଆଗମନ କେବଳ ପ୍ରଥମ ବର୍ଷା ନୁହେଁ; ଏହାର ଅର୍ଥ ଲଗାତର ବର୍ଷାର ଆରମ୍ଭ। ଦୟାକରି ଏହାକୁ ଆପଣଙ୍କ ଅଞ୍ଚଳର ଅନ୍ୟ ଚାଷୀଙ୍କୁ ପଠାନ୍ତୁ। ସଠିକ୍ ଆକଳନ ଉପଲବ୍ଧ ହେଲେ ଏହାକୁ ପଠାଯିବ। ଦୟାକରି ଧ୍ୟାନ ଦିଅନ୍ତୁ, ପ୍ରକୃତ ବର୍ଷା ପାଗ ପରିସ୍ଥିତିର ଆକଳନଠାରୁ ଅଲଗା ହୋଇପାରେ। <Attribution to be hyperlinked here> | E2: কৃষকদের জন্য তথ্য: কৃষি মন্ত্রণালয় এই নম্বর থেকে SMS করে আপনার এলাকায় এই বছর বর্ষাকাল কখন আসবে সে সম্পর্কে আপডেট পাঠাবে। বর্ষাকালের আগমন মানে কেবল প্রথম বৃষ্টিপাত নয়; এর অর্থ হল অবিরাম বৃষ্টিপাতের শুরু। আপনার এলাকার অন্যান্য কৃষকদের সাথে এটি শেয়ার করুন। সঠিক অনুমান পাওয়া গেলে তা শেয়ার করা হবে। অনুগ্রহ করে মনে রাখবেন: প্রকৃত বর্ষাকাল পরিস্থিতি, অনুমানের থেকে ভিন্ন হতে পারে। <Attribution to be hyperlinked here> | F2: రైతులకు సమాచారం: వ్యవసాయ మంత్రిత్వశాఖ ఈ సంవత్సరం మీ ప్రాంతంలో వర్షాకాల ప్రారంభ అవకాశం పై ఈ నెంబర్ నుండి SMSలు పంపిస్తారు. వర్షాకాల ప్రారంభం అంటే కేవలం మొదటి వర్షపాతం కాదు; నిరంతర వర్షపాతం ప్రారంభం అని అర్థం. ఈ సమాచారాన్ని మీ ప్రాంతంలోని ఇతర రైతులతో పంచుకోండి. కచ్చితమైన సూచనలు అందుబాటులో ఉన్నప్పుడు మీకు పంపిస్తాము. దయచేసి గమనించండి, అసలు వర్షాకాల పరిస్థితులు ఈ సూచన నుండి వేరుగా ఉండవచ్చు. <Attribution to be hyperlinked here> | G2: ರೈತರಿಗೆ ಮಾಹಿತಿ: ಕೃಷಿ ಸಚಿವಾಲಯವು ಈ ವರ್ಷ ನಿಮ್ಮ ಪ್ರದೇಶದಲ್ಲಿ ಯಾವಾಗ ಮಳೆಗಾಲ ಆಗಮನವಾಗುತ್ತದೆ ಎನ್ನುವ ಸಾಧ್ಯತೆಯನ್ನು ಈ ಸಂಖ್ಯೆಯಿಂದ SMS ಗಳ ಮೂಲಕ ಕಳಿಸುತ್ತದೆ. ಮಳೆಗಾಲದ ಆಗಮನ ಎಂದರೆ ಮೊದಲ ಮಳೆ ಎಂದರ್ಥವಲ್ಲ; ಇದರರ್ಥ ನಿರಂತರ ಮಳೆಯ ಪ್ರಾರಂಭ. ದಯವಿಟ್ಟು ಇದನ್ನು ನಿಮ್ಮ ಪ್ರದೇಶದ ಇತರ ರೈತರೊಂದಿಗೆ ಹಂಚಿಕೊಳ್ಳಿ. ಲಭ್ಯವಿದ್ದಾಗ ನಿಖರವಾದ ಮುನ್ಸೂಚನೆಗಳ್ಳನ್ನು ಹಂಚಿಕೊಳ್ಳಲಾಗುತ್ತದೆ. ದಯವಿಟ್ಟು ಗಮನಿಸಿ: ಮಳೆಗಾಲದ ಪರಿಸ್ಥಿತಿಗಳು ಮುನ್ಸೂಚನೆಗಿಂತ ಭಿನ್ನವಾಗಿರಬಹುದು. <Attribution to be hyperlinked here> | H2: ਕਿਸਾਨਾਂ ਲਈ ਜਾਣਕਾਰੀ: ਖੇਤੀਬਾੜੀ ਮੰਤਰਾਲਾ ਇਸ ਨੰਬਰ ਤੋਂ ਤੁਹਾਡੇ ਇਲਾਕੇ ਵਿੱਚ ਇਸ ਸਾਲ ਵਰਖਾ ਦੇ ਮੌਸਮ ਦੇ ਕਦੋਂ ਆਉਣ ਦੀ ਸੰਭਾਵਨਾ ਹੈ, ਬਾਰੇ SMS ਭੇਜੇਗਾ। ਵਰਖਾ ਦਾ ਮੌਸਮ ਆਉਣਾ ਸਿਰਫ ਪਹਿਲੀ ਬਰਸਾਤ ਦਾ ਮਤਲਬ ਨਹੀਂ ਹੈ; ਇਸਦਾ ਮਤਲਬ ਹੈ ਲਗਾਤਾਰ ਵਰਖਾ ਦੀ ਸ਼ੁਰੂਆਤ। ਇਸ ਨੂੰ ਆਪਣੇ ਇਲਾਕੇ ਦੇ ਹੋਰ ਕਿਸਾਨਾਂ ਨਾਲ ਸਾਂਝਾ ਕਰੋ। ਜਦੋਂ ਉਪਲਬਧ ਹੋਵੇ, ਸਹੀ ਅੰਦਾਜੇ ਸਾਂਝੇ ਕੀਤੇ ਜਾਣਗੇ। ਕਿਰਪਾ ਕਰਕੇ ਧਿਆਨ ਰੱਖੋ: ਅਸਲ ਵਰਖਾ ਦੇ ਮੌਸਮ ਦੀ ਹਕੀਕਤ ਅੰਦਾਜੇ ਤੋਂ ਵੱਖਰੀ ਹੋ ਸਕਦੀ ਹੈ। <Attribution to be hyperlinked here>

Sheet PM2
A1: eng | B1: hin | C1: mar | D1: odi | E1: ben | F1: tel | G1: kan | H1: pun
A2: Information for farmers: You will continue to receive SMS upDates from this number about when the rainy season is likely to arrive in your locality this year. The arrival of the rainy season does not just mean the first rainfall; it means the start of continuous rains. Please share this with other farmers in your locality. Accurate estimates will be shared when available. Please note: Real rainy season conditions may vary from the estimate. <Attribution to be hyperlinked here> | B2: किसानों के लिए जानकारी: बरसात का मौसम आने की संभावना के बारे में आपको इस नंबर से SMS अपडेट मिलते रहेंगे। बारिश का मौसम आने का मतलब बस पहली बारिश नहीं है, इसका मतलब है लगातार बारिश की शुरुआत| कृपया इसे अपने इलाके के अन्य किसानों के साथ साझा करें। सटीक अनुमान उपलब्ध होने पर भेजे जाएंगे। कृपया ध्यान दें: असली बारिश का मौसम की स्थिति अनुमान से अलग हो सक्ती है। <Attribution to be hyperlinked here> | C2: शेतकऱ्यांसाठी माहिती – या वर्षी तुमच्या भागात पावसाळा कधी सुरू होईल, याबाबत तुम्हाला या क्रमांकावरून SMS येत राहतील. पावसाळा सुरू होणे म्हणजे फक्त पहिला पाऊस नव्हे, तर सलग पावसाची सुरुवात होय. कृपया ही माहिती आपल्या भागातील इतर शेतकऱ्यांपर्यंत पोहोचवा. अचूक अंदाज मिळाल्यावर शेअर केला जाईल. लक्षात ठेवा: पावसाळ्याची खरी परिस्थिती अंदाजापेक्षा वेगळी असू शकते. <Attribution to be hyperlinked here> | D2: କୃଷକମାନଙ୍କ ପାଇଁ ସୂଚନା: ଏହି ବର୍ଷ ଆପଣଙ୍କ ଅଞ୍ଚଳରେ ବର୍ଷା ଋତୁ କେବେ ଆସିବ ସେ ବିଷୟରେ ଆପଣଙ୍କୁ ଏହି ନମ୍ବରରୁ SMS ମାଧ୍ୟମ ରେ ସୂଚନା ମିଳିବ। ବର୍ଷା ଋତୁର ଆଗମନ କେବଳ ପ୍ରଥମ ବର୍ଷା ନୁହେଁ; ଏହାର ଅର୍ଥ ଲଗାତର ବର୍ଷାର ଆରମ୍ଭ। ଦୟାକରି ଏହାକୁ ଆପଣଙ୍କ ଅଞ୍ଚଳର ଅନ୍ୟ ଚାଷୀଙ୍କୁ ପଠାନ୍ତୁ। ସଠିକ୍ ଆକଳନ କରାଗଲେ ଏହାକୁ ପଠାଯିବ। ଦୟାକରି ଧ୍ୟାନ ଦିଅନ୍ତୁ, ପ୍ରକୃତ ବର୍ଷା ପାଗ ପରିସ୍ଥିତିର ଆକଳନଠାରୁ ଅଲଗା ହୋଇପାରେ। <Attribution to be hyperlinked here> | E2: কৃষকদের জন্য তথ্য: এই বছর আপনার এলাকায় বর্ষাকাল কখন আসবে সে সম্পর্কে এই নম্বর থেকে আপনি SMS আপডেট পেতে থাকবেন। বর্ষাকালের আগমন মানে কেবল প্রথম বৃষ্টিপাত নয়; এর অর্থ হল অবিরাম বৃষ্টিপাতের শুরু। আপনার এলাকার অন্যান্য কৃষকদের সাথে এটি শেয়ার করুন। সঠিক অনুমান পাওয়া গেলে তা শেয়ার করা হবে। অনুগ্রহ করে মনে রাখবেন: প্রকৃত বর্ষাকাল পরিস্থিতি, অনুমানের থেকে ভিন্ন হতে পারে। <Attribution to be hyperlinked here> | F2: రైతులకు సమాచారం: ఈ సంవత్సరం మీ ప్రాంతంలో వర్షాకాల ప్రారంభ అవకాశం పై ఈ నెంబర్ నుండి SMSలు ఎప్పటికప్పుడు అందుకుంటూ ఉంటారు. వర్షాకాల ప్రారంభం అంటే కేవలం మొదటి వర్షపాతం కాదు; నిరంతర వర్షపాతం ప్రారంభం అని అర్థం. ఈ సమాచారాన్ని మీ ప్రాంతంలోని ఇతర రైతులతో పంచుకోండి. కచ్చితమైన సూచనలు అందుబాటులో ఉన్నప్పుడు మీకు పంపిస్తాము. దయచేసి గమనించండి, అసలు వర్షాకాల పరిస్థితులు ఈ సూచన నుండి వేరుగా ఉండవచ్చు. <Attribution to be hyperlinked here> | G2: ರೈತರಿಗೆ ಮಾಹಿತಿ: ಈ ವರ್ಷ ನಿಮ್ಮ ಪ್ರದೇಶದಲ್ಲಿ ಯಾವಾಗ ಮಳೆಗಾಲ ಆಗಮನವಾಗುತ್ತದೆ ಎನ್ನುವ ಸಾಧ್ಯತೆಯನ್ನು ಈ ಸಂಖ್ಯೆಯಿಂದ SMS ಗಳ ಮೂಲಕ ನಿರಂತರವಾಗಿ ಸ್ವೀಕರಿಸುತ್ತೀರಿ. ಮಳೆಗಾಲದ ಆಗಮನ ಎಂದರೆ ಮೊದಲ ಮಳೆ ಎಂದರ್ಥವಲ್ಲ; ಇದರರ್ಥ ನಿರಂತರ ಮಳೆಯ ಪ್ರಾರಂಭ. ದಯವಿಟ್ಟು ಇದನ್ನು ನಿಮ್ಮ ಪ್ರದೇಶದ ಇತರ ರೈತರೊಂದಿಗೆ ಹಂಚಿಕೊಳ್ಳಿ. ಲಭ್ಯವಿದ್ದಾಗ ನಿಖರವಾದ ಮುನ್ಸೂಚನೆಗಳ್ಳನ್ನು ಹಂಚಿಕೊಳ್ಳಲಾಗುತ್ತದೆ. ದಯವಿಟ್ಟು ಗಮನಿಸಿ: ಮಳೆಗಾಲದ ಪರಿಸ್ಥಿತಿಗಳು ಮುನ್ಸೂಚನೆಗಿಂತ ಭಿನ್ನವಾಗಿರಬಹುದು. <Attribution to be hyperlinked here> | H2: ਕਿਸਾਨਾਂ ਲਈ ਜਾਣਕਾਰੀ: ਤੁਹਾਨੂੰ ਇਸ ਨੰਬਰ ਤੋਂ ਇਹ ਜਾਣਕਾਰੀ ਮਿਲਦੀ ਰਹੇਗੀ ਕਿ ਇਸ ਸਾਲ ਵਰਖਾ ਦੇ ਮੌਸਮ ਦੇ ਤੁਹਾਡੇ ਇਲਾਕੇ ਵਿੱਚ ਕਦੋਂ ਆਉਣ ਦੀ ਸੰਭਾਵਨਾ ਹੈ। ਵਰਖਾ ਦਾ ਮੌਸਮ ਆਉਣਾ ਸਿਰਫ ਪਹਿਲੀ ਬਰਸਾਤ ਦਾ ਮਤਲਬ ਨਹੀਂ ਹੈ; ਇਸਦਾ ਮਤਲਬ ਹੈ ਲਗਾਤਾਰ ਵਰਖਾ ਦੀ ਸ਼ੁਰੂਆਤ। ਕਿਰਪਾ ਕਰਕੇ ਇਸ ਨੂੰ ਆਪਣੇ ਇਲਾਕੇ ਦੇ ਹੋਰ ਕਿਸਾਨਾਂ ਨਾਲ ਸਾਂਝਾ ਕਰੋ। ਜਦੋਂ ਉਪਲਬਧ ਹੋਵੇ, ਸਹੀ ਅੰਦਾਜੇ ਸਾਂਝੇ ਕੀਤੇ ਜਾਣਗੇ। ਕਿਰਪਾ ਕਰਕੇ ਧਿਆਨ ਰੱਖੋ: ਅਸਲ ਵਰਖਾ ਦੇ ਮੌਸਮ ਦੀ ਹਕੀਕਤ ਅੰਦਾਜੇ ਤੋਂ ਵੱਖਰੀ ਹੋ ਸਕਦੀ ਹੈ। <Attribution to be hyperlinked here>

Sheet PM_IVRS
B1: odi
A2: Weather forecast information for farmers from Krushi Samrudhi. This Kharif season, you’ll receive weekly upDates [through SMS and voice messages] about the expected start of the continuous rainy season in your locality. "Continuous rainy season" doesn’t just mean the first rain—it means the steady, farming-friendly rainfall. Each week, we will send you the best estimate of [emphasize] WHEN the continuous rain will arrive in your locality and how likely it is that the estimate will be correct. The message will be sent out on Thursdays or Fridays. With changing weather patterns, it’s becoming harder to know when the continuous rain will settle in. These forecasts offer the best estimates, but remember, they are not guarantees—for example, an 80% chance of rain in the time between two Dates means it’s very likely to rain in that period, but there is still a small some chance the rain will come earlier or later. Farmers in many districts will receive these upDates, but not everyone is registered for the service. Watch for the SMS messages and voice calls starting next week, and forward the message or share it with other farmers in your village. Call 155-333 if you have any questions.

Sheet ES1
A1: eng | B1: hin | C1: mar | D1: odi | E1: ben | F1: tel | G1: kan | H1: pun
A2: New weather information for farmers: <SMS Date> <SMS Month> 2025 In your locality, after <Date AA> <Month B>, the possibility of a continuous rainy season arriving is <qual 1>. (XX%, meaning XX in 100) Before <Date AA> <Month B>, the possibility of a continuous rainy season arriving is <qual 2>. (YY%, meaning YY in 100) | B2: किसानों के लिए नई मौसम जानकारी: <SMS Date> <SMS Month> 2025 आपके इलाके में, <Date AA> <Month B> के बाद, लगातार बारिश का मौसम आने की <qual 1> संभावना है| (XX% यानी 100 में से XX) <Date AA> <Month B> के पहले, लगतार बारिश का मौसम आने की <qual 2> संभावना है| (YY% यानी 100 में से YY) प्रेषक: कृषि एवं किसान कल्याण मंत्रालय | C2: शेतकऱ्यांसाठी नवी हवामान माहिती – <SMS Date> <SMS Month> 2025 तुमच्या भागात <Date AA> <Month B> नंतर सलग पावसाळा सुरू होण्याची शक्यता <qual 1> आहे. (XX%, म्हणजे 100 पैकी XX) <Date AA> <Month B> पूर्वी सलग पावसाळा सुरू होण्याची शक्यता <qual 2> आहे. (YY%, म्हणजे 100 पैकी YY) प्रेषक: कृषी आणि शेतकरी कल्याण मंत्रालय | D2: ଚାଷୀଙ୍କ ପାଇଁ ନୂତନ ପାଣିପାଗ ସୂଚନା: <SMS Date> <SMS Month> 2025 ଆପଣଙ୍କ ଅଞ୍ଚଳରେ, <Date AA> <Month B> ପରେ, ଲଗାତର ବର୍ଷା ଋତୁ ଆସିବାର ସମ୍ଭାବନା <qual 1> ଅଟେ। (XX%, ଅର୍ଥାତ୍ 100 ରେ XX) <Date AA> <Month B> ପୂର୍ବରୁ, ଏକ ଲଗାତର ବର୍ଷା ଋତୁ ଆସିବାର ସମ୍ଭାବନା <qual 2> ଅଟେ। (YY%, ଅର୍ଥାତ୍ 100 ରେ YY) ପ୍ରେରକ: କୃଷି ଏବଂ କୃଷକ କଲ୍ୟାଣ ମନ୍ତ୍ରଣାଳୟ | E2: কৃষকদের জন্য নতুন আবহাওয়ার তথ্য: <SMS Date> <SMS Month> 2025 আপনার এলাকায়, <Date AA> <Month B> এর পরে, একটানা বর্ষা আসার <qual 1> সম্ভাবনা। (XX%, অর্থাৎ 100-এর মধ্যে XX ) <Date AA> <Month B> এর আগে, একটানা বর্ষা আসার <qual 2> সম্ভাবনা। (YY%, অর্থাৎ 100-এর মধ্যে YY) কৃষি ও কৃষক কল্যাণ মন্ত্রণালয়” দ্বারা প্রচারিত । | F2: రైతుల కోసం తాజా వాతావరణ సమాచారం: <SMS Date> <SMS Month> 2025 మీ ప్రాంతం లో, <Date AA> <Month B> తర్వాత, నిరంతర వర్షాలు వచ్చేందుకు <qual 1> అవకాశం ఉంది. (XX%, అంటే, 100 లో XX) <Date AA> <Month B> ముందు, నిరంతర వర్షాలు వచ్చేందుకు <qual 2> అవకాశం ఉంది. (YY%, అంటే, 100 లో YY) పంపిస్తున్నది: వ్యవసాయ మరియు రైతు సంక్షేమ మంత్రిత్వ శాఖ | G2: ರೈತರಿಗೆ ಹೊಸ ಹವಾಮಾನ ಮಾಹಿತಿ: <SMS Date> <SMS Month> 2025 ನಿಮ್ಮ ಪ್ರದೇಶದಲ್ಲಿ, <Date AA> <Month B> ರ ನಂತರ, ನಿರಂತರ ಮಳೆ ಬರುವ ಸಾಧ್ಯತೆ <qual 1> . (XX%, ಅಂದರೆ 100 ರಲ್ಲಿ XX) <Date AA> <Month B> ಗಿಂತ ಮುಂಚೆ, ನಿರಂತರ ಮಳೆ ಬರುವ ಸಾಧ್ಯತೆ <qual 2>. (YY%, ಅಂದರೆ 100 ರಲ್ಲಿ YY) ಪ್ರಾಯೋಜಕರು: ಕೃಷಿ ಮತ್ತು ರೈತರ ಕಲ್ಯಾಣ ಸಚಿವಾಲಯ | H2: ਕਿਸਾਨਾਂ ਲਈ ਨਵਾਂ ਮੌਸਮ ਜਾਣਕਾਰੀ: <SMS Date> <SMS Month> 2025 ਤੁਹਾਡੇ ਇਲਾਕੇ ਵਿੱਚ, <Date AA> <Month B> ਤੋਂ ਬਾਅਦ ਲਗਾਤਾਰ ਵਰਖਾ ਦੇ ਮੌਸਮ ਦੇ ਆਉਣ ਦੀ ਸੰਭਾਵਨਾ <qual 1> ਹੈ। (XX%, ਮਤਲਬ 100 ਵਿੱਚੋਂ XX) <Date AA> <Month B> ਤੋਂ ਪਹਿਲਾਂ, ਲਗਾਤਾਰ ਵਰਖਾ ਦੇ ਮੌਸਮ ਦੇ ਆਉਣ ਦੀ ਸੰਭਾਵਨਾ <qual 2> ਹੈ। (YY%, ਮਤਲਬ 100 ਵਿੱਚੋਂ YY) ਭੇਜਣ ਵਾਲਾ: ਖੇਤੀਬਾੜੀ ਅਤੇ ਕਿਸਾਨ ਭਲਾਈ ਮੰਤਰਾਲਾ

Sheet ES2
A1: eng | B1: hin | C1: mar | D1: odi | E1: ben | F1: tel | G1: kan | H1: pun
A2: New weather information for farmers: <SMS Date> <SMS Month> 2025 In your locality, after <Date AA> <Month B>, the possibility of a continuous rainy season arriving is <qual 1>. (XX%, meaning XX in 100) | B2: किसानों के लिए नई मौसम जानकारी: <SMS Date> <SMS Month> 2025 आपके इलाके में, <Date AA> <Month B> के बाद, लगातार बारिश का मौसम आने की <qual 1> संभावना है| (XX% यानी 100 में से XX) | C2: शेतकऱ्यांसाठी नवी हवामान माहिती – <SMS Date> <SMS Month> 2025 तुमच्या भागात <Date AA> <Month B> नंतर सलग पावसाळा सुरू होण्याची शक्यता <qual 1> आहे. (XX%, म्हणजे 100 पैकी XX) | D2: ଚାଷୀଙ୍କ ପାଇଁ ନୂତନ ପାଣିପାଗ ସୂଚନା: <SMS Date> <SMS Month> 2025 ଆପଣଙ୍କ ଅଞ୍ଚଳରେ, <Date AA> <Month B> ପରେ, ଲଗାତର ବର୍ଷା ଋତୁ ଆସିବାର ସମ୍ଭାବନା <qual 1> ଅଟେ। (XX%, ଅର୍ଥାତ୍ 100 ରେ XX) | E2: কৃষকদের জন্য নতুন আবহাওয়ার তথ্য: <SMS Date> <SMS Month> 2025 আপনার এলাকায়, <Date AA> <Month B> এর পরে, একটানা বর্ষা আসার <qual 1> সম্ভাবনা। (XX%, অর্থাৎ 100-এর মধ্যে XX ) | F2: రైతుల కోసం తాజా వాతావరణ సమాచారం: <SMS Date> <SMS Month> 2025 మీ ప్రాంతం లో, <Date AA> <Month B> తర్వాత, నిరంతర వర్షాలు వచ్చేందుకు <qual 1> అవకాశం ఉంది. (XX%, అంటే, 100 లో XX) | G2: ರೈತರಿಗೆ ಹೊಸ ಹವಾಮಾನ ಮಾಹಿತಿ: <SMS Date> <SMS Month> 2025 ನಿಮ್ಮ ಪ್ರದೇಶದಲ್ಲಿ, <Date AA> <Month B> ರ ನಂತರ, ನಿರಂತರ ಮಳೆ ಬರುವ ಸಾಧ್ಯತೆ <qual 1> . (XX%, ಅಂದರೆ 100 ರಲ್ಲಿ XX) | H2: ਕਿਸਾਨਾਂ ਲਈ ਨਵਾਂ ਮੌਸਮ ਜਾਣਕਾਰੀ: <SMS Date> <SMS Month> 2025 ਤੁਹਾਡੇ ਇਲਾਕੇ ਵਿੱਚ, <Date AA> <Month B> ਤੋਂ ਬਾਅਦ ਲਗਾਤਾਰ ਵਰਖਾ ਦੇ ਮੌਸਮ ਦੇ ਆਉਣ ਦੀ ਸੰਭਾਵਨਾ <qual 1> ਹੈ। (XX%, ਮਤਲਬ 100 ਵਿੱਚੋਂ XX)

Sheet ES1_IVRS
A1: eng | B1: odi
A2: This is new weather forecast information for farmers from Krushi Samruddhi, about [emphasize] when the rainy season is likely to arrive for your locality. This message was recorded on <SMS Date> <SMS Month> 2025 . Continuous rains will [emphasize] MOST LIKELY arrive AFTER [emphasize] <Date AA> <Month B> in your locality. There is a [emphasize] <qual 1> chance, around XX%, that this forecast will be correct. The possibility of the continuous rains arriving BEFORE [emphasize] <Date AA> <Month B> in your locality is [emphasize] <qual 2>, at around YY%. Remember, the continuous rainy season doesn’t just mean the first rain—it means the steady, farming-friendly rainfall. Again, continuous rains will [emphasize] MOST LIKELY arrive AFTER [emphasize] <Date AA> <Month B> in your locality. There is a [emphasize] <qual 1> chance, around XX%, that this forecast will be correct. We will call you with an upDate on Thursday or Friday. If you have any questions, please call 155-333 for more information. | B2: ଏହା କୃଷି ସମୃଦ୍ଧିର ଚାଷୀଙ୍କ ପାଇଁ ନୂତନ ପାଣିପାଗ ପୂର୍ବାନୁମାନ ସୂଚନା, ଆପଣଙ୍କ ଅଞ୍ଚଳରେ ମୌସୁମୀ ବର୍ଷା [ଗୁରୁତ୍ୱ ଦିଅନ୍ତୁ] କେବେ ଆସିବାର ସମ୍ଭାବନା ଅଛି ସେ ବିଷୟରେ । ଏହି ସୂଚନା <SMS Date> <SMS Month> 2025 ରେ ପ୍ରସ୍ତୁତ କରାଯାଇଥିଲା। ଆପଣଙ୍କ ଅଞ୍ଚଳରେ [ଗୁରୁତ୍ୱ ଦିଅନ୍ତୁ] <Date AA> <Month B> ପରେ ଲଗାତାର ମୌସୁମୀ ବର୍ଷା ହେବାର [ଗୁରୁତ୍ୱ ଦିଅନ୍ତୁ] ସର୍ବାଧିକ ସମ୍ଭାବନା ଅଛି। ଏହି ପୂର୍ବାନୁମାନ ସଠିକ୍ ହେବାର ପ୍ରାୟ [ଗୁରୁତ୍ୱ ଦିଅନ୍ତୁ] XX% ସମ୍ଭାବନା ଅଛି, ଯାହାକି <qual 1>। ଆପଣଙ୍କ ଅଞ୍ଚଳରେ <Date AA> <Month B> [ଗୁରୁତ୍ୱ ଦିଅନ୍ତୁ] ପୂର୍ବରୁ ଲଗାତାର ମୌସୁମୀ ବର୍ଷା ହେବାର ସମ୍ଭାବନା [ଗୁରୁତ୍ୱ ଦିଅନ୍ତୁ] <qual 2> ଅଟେ, ଯାହା ପ୍ରାୟ YY%। ମନେରଖନ୍ତୁ, ଲଗାତାର ମୌସୁମୀ ବର୍ଷା କେବଳ ପ୍ରଥମ ବର୍ଷା ନୁହେଁ - ଏହାର ଅର୍ଥ ନିୟମିତ, କୃଷି-ଅନୁକୂଳ ବର୍ଷା। ପୁନର୍ବାର, ଆପଣଙ୍କ ଅଞ୍ଚଳରେ [ଗୁରୁତ୍ୱ ଦିଅନ୍ତୁ]<Date AA> <Month B> ପରେ ଲଗାତର ମୌସୁମୀ ବର୍ଷା ହେବାର[ଗୁରୁତ୍ୱ ଦିଅନ୍ତୁ] ସର୍ବାଧିକ ସମ୍ଭାବନା ଅଛି। ଏହି ପୂର୍ବାନୁମାନ ସୂଚନା ସଠିକ୍ ହେବାର ପ୍ରାୟ XX% ସମ୍ଭାବନା ଅଛି,[ଗୁରୁତ୍ୱ ଦିଅନ୍ତୁ] <qual 1> ଧରଣର। ଆମେ ଗୁରୁବାର କିମ୍ବା ଶୁକ୍ରବାର ଦିନ ଫୋନ କରି ଆପଣଙ୍କୁ ଅପଡେଟ ଜଣାଇବୁ । ଯଦି ଆପଣଙ୍କର କୌଣସି ପ୍ରଶ୍ନ ଅଛି, ତେବେ ଅଧିକ ସୂଚନା ପାଇଁ ଦୟାକରି 155-333 କୁ କଲ୍ କରନ୍ତୁ।

Sheet LS1
A1: eng | B1: hin | C1: mar | D1: odi | E1: ben | F1: tel | G1: kan | H1: pun
A2: New weather information for farmers: <SMS Date> <SMS Month> 2025 In your locality, from <Date AA> <Month B> to <Date CC> <Month D>, the possibility of a continuous rainy season arriving is highest. (XX%, meaning XX in 100) Before <Date AA> <Month B>, the possibility of a continuous rainy season arriving is <qual 1>. (YY%, meaning YY in 100) After <Date CC> <Month D>, the possibility of a continuous rainy season arriving is <qual 2>. (ZZ%, meaning ZZ in 100) | B2: किसानों के लिए नई मौसम जानकारी: <SMS Date> <SMS Month> 2025 आपके इलाके में, <Date AA> <Month B> से <Date CC> <Month D> के बीच, लगतार बारिश का मौसम आने की सबसे अधिक संभावना है| (XX% यानी 100 में से XX) <Date AA> <Month B> के पहले, लगतार बारिश का मौसम आने की <qual 1> संभावना है| (YY% यानी 100 में से YY) <Date CC> <Month D> के बाद, लगतार बारिश का मौसम आने की <qual 2> संभावना है| (ZZ% यानी 100 में से ZZ) प्रेषक: कृषि एवं किसान कल्याण मंत्रालय | C2: शेतकऱ्यांसाठी नवी हवामान माहिती – <SMS Date> <SMS Month> 2025 तुमच्या भागात <Date AA> <Month B> ते <Date CC> <Month D> दरम्यान सलग पावसाळा सुरू होण्याची शक्यता सर्वाधिक आहे. (XX%, म्हणजे 100 पैकी XX) <Date AA> <Month B> पूर्वी सलग पावसाळा सुरू होण्याची शक्यता <qual 1> आहे. (YY%, म्हणजे 100 पैकी YY) <Date CC> <Month D> नंतर सलग पावसाळा सुरू होण्याची शक्यता <qual 2> आहे. (ZZ%, म्हणजे 100 पैकी ZZ) प्रेषक: कृषी आणि शेतकरी कल्याण मंत्रालय | D2: ଚାଷୀଙ୍କ ପାଇଁ ନୂତନ ପାଣିପାଗ ସୂଚନା: <SMS Date> <SMS Month> 2025 ଆପଣଙ୍କ ଅଞ୍ଚଳରେ, <Date AA> <Month B> ରୁ <Date CC> <Month D> ପର୍ଯ୍ୟନ୍ତ, ଲଗାତର ବର୍ଷା ଋତୁ ଆସିବାର ସମ୍ଭାବନା ସର୍ବାଧିକ। (XX%, ଅର୍ଥାତ୍ 100 ରେ XX) <Date AA> <Month B> ପୂର୍ବରୁ, ଏକ ଲଗାତର ବର୍ଷା ଋତୁ ଆସିବାର ସମ୍ଭାବନା <qual 1> ଅଟେ। (YY%, ଅର୍ଥାତ୍ 100 ରେ YY) <Date CC> <Month D> ପରେ , ଏକ ଲଗାତର ବର୍ଷା ଋତୁ ଆସିବାର ସମ୍ଭାବନା <qual 2> ଅଟେ। (ZZ%, ଅର୍ଥାତ୍ 100 ରେ ZZ) ପ୍ରେରକ: କୃଷି ଏବଂ କୃଷକ କଲ୍ୟାଣ ମନ୍ତ୍ରଣାଳୟ | E2: কৃষকদের জন্য নতুন আবহাওয়ার তথ্য: <10> <August> 2025 আপনার এলাকায়, <Date AA> <Month B> থেকে <Date CC> <Month D> পর্যন্ত, একটানা বর্ষা আসার অত্যাধিক সম্ভাবনা। (XX%, অর্থাৎ 100-এর মধ্যে XX ) <Date AA> <Month B> এর আগে, একটানা বর্ষা আসার <qual 1> সম্ভাবনা। (YY%, অর্থাৎ 1০০-এর মধ্যে YY) <Date CC> <Month D> এর পরে, একটানা বর্ষা আসার <qual 2> সম্ভাবনা। (ZZ%, অর্থাৎ 1০০-এর মধ্যে ZZ) কৃষি ও কৃষক কল্যাণ মন্ত্রণালয়” দ্বারা প্রচারিত । | F2: రైతుల కోసం తాజా వాతావరణ సమాచారం: <SMS Date> <SMS Month> 2025 మీ ప్రాంతంలో, <Date AA> <Month B> నుండి <Date CC> <Month D> మధ్య, నిరంతర వర్షాలు వచ్చేందుకు అత్యధిక అవకాశం ఉంది. (XX%, అంటే, 100 లో XX) <Date AA> <Month B> ముందు, నిరంతర వర్షాలు వచ్చేందుకు <qual 1> అవకాశం ఉంది. (YY%, అంటే, 100 లో YY) <Date CC> <Month D> తర్వాత, నిరంతర వర్షాలు వచ్చేందుకు <qual 2> అవకాశం ఉంది. (ZZ%, అంటే, 100 లో ZZ) పంపిస్తున్నది: వ్యవసాయ మరియు రైతు సంక్షేమ మంత్రిత్వ శాఖ | G2: ರೈತರಿಗೆ ಹೊಸ ಹವಾಮಾನ ಮಾಹಿತಿ: <SMS Date> <SMS Month> 2025 ನಿಮ್ಮ ಪ್ರದೇಶದಲ್ಲಿ, <Date AA> <Month B> ರಿಂದ <Date CC> <Month D> ರವರೆಗೆ, ನಿರಂತರ ಮಳೆ ಬರುವ ಸಾಧ್ಯತೆ ಹೆಚ್ಚು. (XX%, ಅಂದರೆ 100 ರಲ್ಲಿ XX) <Date AA> <Month B> ಕ್ಕಿಂತ ಮುಂಚೆ , ನಿರಂತರ ಮಳೆ ಬರುವ ಸಾಧ್ಯತೆ <qual 1>. (YY%, ಅಂದರೆ 100 ರಲ್ಲಿ YY) <Date CC> <Month D>ರ ನಂತರ, ನಿರಂತರ ಮಳೆ ಬರುವ ಸಾಧ್ಯತೆ <qual 2>. (ZZ%, ಅಂದರೆ 100 ರಲ್ಲಿ ZZ) ಪ್ರಾಯೋಜಕರು: ಕೃಷಿ ಮತ್ತು ರೈತರ ಕಲ್ಯಾಣ ಸಚಿವಾಲಯ | H2: ਕਿਸਾਨਾਂ ਲਈ ਨਵਾਂ ਮੌਸਮ ਜਾਣਕਾਰੀ: <SMS Date> <SMS Month> 2025 ਤੁਹਾਡੇ ਇਲਾਕੇ ਵਿੱਚ, <Date AA> <Month B> ਤੋਂ <Date CC> <Month D> ਤੱਕ ਲਗਾਤਾਰ ਬਾਰਸ਼ੀ ਮੌਸਮ ਆਉਣ ਦੀ ਸੰਭਾਵਨਾ ਸਭ ਤੋਂ ਵੱਧ ਹੈ। (XX%, ਮਤਲਬ 100 ਵਿੱਚੋਂ XX) <Date AA> <Month B> ਤੋਂ ਪਹਿਲਾਂ, ਲਗਾਤਾਰ ਬਾਰਸ਼ੀ ਮੌਸਮ ਆਉਣ ਦੀ ਸੰਭਾਵਨਾ <qual 1>ਹੈ। (YY%, ਮਤਲਬ 100 ਵਿੱਚੋਂ YY) <Date CC> <Month D> ਤੋਂ ਬਾਅਦ, ਲਗਾਤਾਰ ਬਾਰਸ਼ੀ ਮੌਸਮ ਆਉਣ ਦੀ ਸੰਭਾਵਨਾ <qual 2>ਹੈ। (ZZ%, ਮਤਲਬ 100 ਵਿੱਚੋਂ ZZ) ਭੇਜਣ ਵਾਲਾ: ਖੇਤੀਬਾੜੀ ਅਤੇ ਕਿਸਾਨ ਭਲਾਈ ਮੰਤਰਾਲਾ

Sheet LS2
A1: eng | B1: hin | C1: mar | D1: odi | E1: ben | F1: tel | G1: kan | H1: pun
A2: New weather information for farmers: <SMS Date> <SMS Month> 2025 In your locality, from <Date AA> <Month B> to <Date CC> <Month D>, the possibility of a continuous rainy season arriving is highest. (XX%, meaning XX in 100) | B2: किसानों के लिए नई मौसम जानकारी: <SMS Date> <SMS Month> 2025 आपके इलाके में, <Date AA> <Month B> से <Date CC> <Month D> के बीच, लगतार बारिश का मौसम आने की सबसे अधिक संभावना है| (XX% यानी 100 में से XX) | C2: शेतकऱ्यांसाठी नवी हवामान माहिती – <SMS Date> <SMS Month> 2025 तुमच्या भागात <Date AA> <Month B> ते <Date CC> <Month D> दरम्यान सलग पावसाळा सुरू होण्याची शक्यता सर्वाधिक आहे. (XX%, म्हणजे 100 पैकी XX) | D2: ଚାଷୀଙ୍କ ପାଇଁ ନୂତନ ପାଣିପାଗ ସୂଚନା: <SMS Date> <SMS Month> 2025 ଆପଣଙ୍କ ଅଞ୍ଚଳରେ, <Date AA> <Month B> ରୁ <Date CC> <Month D> ପର୍ଯ୍ୟନ୍ତ, ଲଗାତର ବର୍ଷା ଋତୁ ଆସିବାର ସମ୍ଭାବନା ସର୍ବାଧିକ। (XX%, ଅର୍ଥାତ୍ 100 ରେ XX) | E2: কৃষকদের জন্য নতুন আবহাওয়ার তথ্য: <10> <August> 2025 আপনার এলাকায়, <Date AA> <Month B> থেকে <Date CC> <Month D> পর্যন্ত, একটানা বর্ষা আসার অত্যাধিক সম্ভাবনা। (XX%, অর্থাৎ 100-এর মধ্যে XX ) | F2: రైతుల కోసం తాజా వాతావరణ సమాచారం: <SMS Date> <SMS Month> 2025 మీ ప్రాంతంలో, <Date AA> <Month B> నుండి <Date CC> <Month D> మధ్య, నిరంతర వర్షాలు వచ్చేందుకు అత్యధిక అవకాశం ఉంది. (XX%, అంటే, 100 లో XX) | G2: ರೈತರಿಗೆ ಹೊಸ ಹವಾಮಾನ ಮಾಹಿತಿ: <SMS Date> <SMS Month> 2025 ನಿಮ್ಮ ಪ್ರದೇಶದಲ್ಲಿ, <Date AA> <Month B> ರಿಂದ <Date CC> <Month D> ರವರೆಗೆ, ನಿರಂತರ ಮಳೆ ಬರುವ ಸಾಧ್ಯತೆ ಹೆಚ್ಚು. (XX%, ಅಂದರೆ 100 ರಲ್ಲಿ XX) | H2: ਕਿਸਾਨਾਂ ਲਈ ਨਵਾਂ ਮੌਸਮ ਜਾਣਕਾਰੀ: <SMS Date> <SMS Month> 2025 ਤੁਹਾਡੇ ਇਲਾਕੇ ਵਿੱਚ, <Date AA> <Month B> ਤੋਂ <Date CC> <Month D> ਤੱਕ ਲਗਾਤਾਰ ਬਾਰਸ਼ੀ ਮੌਸਮ ਆਉਣ ਦੀ ਸੰਭਾਵਨਾ ਸਭ ਤੋਂ ਵੱਧ ਹੈ। (XX%, ਮਤਲਬ 100 ਵਿੱਚੋਂ XX)

Sheet LS3
A1: eng | B1: hin | C1: mar | D1: odi | E1: ben | F1: tel | G1: kan | H1: pun
A2: New weather information for farmers: <SMS Date> <SMS Month> 2025 In your locality, before <Date AA> <Month B>, the possibility of a continuous rainy season arriving is <qual 1>. (XX%, meaning XX in 100) After <Date AA> <Month B>, the possibility of a continuous rainy season arriving is <qual 2>. (YY%, meaning YY in 100) | B2: किसानों के लिए नई मौसम जानकारी: <SMS Date> <SMS Month> 2025 आपके इलाके में, <Date AA> <Month B> के पहले, लगतार बारिश का मौसम आने की <qual 1> संभावना है| (XX% यानी 100 में से XX) <Date AA> <Month B> के बाद, लगातार बारिश का मौसम आने की <qual 2> संभावना है| (YY% यानी 100 में से YY) प्रेषक: कृषि एवं किसान कल्याण मंत्रालय | C2: शेतकऱ्यांसाठी नवी हवामान माहिती – <SMS Date> <SMS Month> 2025 तुमच्या भागात <Date AA> <Month B> पूर्वी सलग पावसाळा सुरू होण्याची शक्यता <qual 1> आहे. (XX%, म्हणजे 100 पैकी XX) <Date AA> <Month B> नंतर सलग पावसाळा सुरू होण्याची शक्यता <qual 1> आहे. (YY%, म्हणजे 100 पैकी YY) प्रेषक: कृषी आणि शेतकरी कल्याण मंत्रालय | D2: ଚାଷୀଙ୍କ ପାଇଁ ନୂତନ ପାଣିପାଗ ସୂଚନା: <SMS Date> <SMS Month> 2025 ଆପଣଙ୍କ ଅଞ୍ଚଳରେ, <Date AA> <Month B> ପୂର୍ବରୁ, ଏକ ଲଗାତର ବର୍ଷା ଋତୁ ଆସିବାର ସମ୍ଭାବନା <qual 1> ଅଟେ। (XX%, ଅର୍ଥାତ୍ 100 ରେ XX) <Date AA> <Month B> ପରେ, ଲଗାତର ବର୍ଷା ଋତୁ ଆସିବାର ସମ୍ଭାବନା <qual 2> ଅଟେ। (YY%, ଅର୍ଥାତ୍ 100 ରେ YY) ପ୍ରେରକ: କୃଷି ଏବଂ କୃଷକ କଲ୍ୟାଣ ମନ୍ତ୍ରଣାଳୟ | E2: কৃষকদের জন্য নতুন আবহাওয়ার তথ্য: <SMS Date> <SMS Month> 2025 আপনার এলাকায়, <Date AA> <Month B> এর আগে, একটানা বর্ষা আসার <qual 1> সম্ভাবনা। (XX%, অর্থাৎ 100-এর মধ্যে XX) <Date AA> <Month B> এর পরে, একটানা বর্ষা আসার <qual 2> সম্ভাবনা। (YY%, অর্থাৎ 100-এর মধ্যে YY ) কৃষি ও কৃষক কল্যাণ মন্ত্রণালয়” দ্বারা প্রচারিত । | F2: రైతుల కోసం తాజా వాతావరణ సమాచారం: <SMS Date> <SMS Month> 2025 మీ ప్రాంతం లో, <Date AA> <Month B> ముందు, నిరంతర వర్షాలు వచ్చేందుకు <qual 1> అవకాశం ఉంది. (XX%, అంటే, 100 లో XX) <Date AA> <Month B> తర్వాత, నిరంతర వర్షాలు వచ్చేందుకు <qual 2> అవకాశం ఉంది. (YY%, అంటే, 100 లో YY) పంపిస్తున్నది: వ్యవసాయ మరియు రైతు సంక్షేమ మంత్రిత్వ శాఖ | G2: ರೈತರಿಗೆ ಹೊಸ ಹವಾಮಾನ ಮಾಹಿತಿ: <SMS Date> <SMS Month> 2025 ನಿಮ್ಮ ಪ್ರದೇಶದಲ್ಲಿ, <Date AA> <Month B> ಗಿಂತ ಮುಂಚೆ, ನಿರಂತರ ಮಳೆ ಬರುವ ಸಾಧ್ಯತೆ <qual 1>. (XX%, ಅಂದರೆ 100 ರಲ್ಲಿ XX) <Date AA> <Month B> ರ ನಂತರ, ನಿರಂತರ ಮಳೆ ಬರುವ ಸಾಧ್ಯತೆ <qual 2> . (YY%, ಅಂದರೆ 100 ರಲ್ಲಿ YY) ಪ್ರಾಯೋಜಕರು: ಕೃಷಿ ಮತ್ತು ರೈತರ ಕಲ್ಯಾಣ ಸಚಿವಾಲಯ | H2: ਕਿਸਾਨਾਂ ਲਈ ਨਵਾਂ ਮੌਸਮ ਜਾਣਕਾਰੀ: <SMS Date> <SMS Month> 2025 ਤੁਹਾਡੇ ਇਲਾਕੇ ਵਿੱਚ, <Date AA> <Month B> ਤੋਂ ਪਹਿਲਾਂ, ਲਗਾਤਾਰ ਵਰਖਾ ਦੇ ਮੌਸਮ ਦੇ ਆਉਣ ਦੀ ਸੰਭਾਵਨਾ <qual 1> ਹੈ। (XX%, ਮਤਲਬ 100 ਵਿੱਚੋਂ XX) <Date AA> <Month B> ਤੋਂ ਬਾਅਦ ਲਗਾਤਾਰ ਵਰਖਾ ਦੇ ਮੌਸਮ ਦੇ ਆਉਣ ਦੀ ਸੰਭਾਵਨਾ <qual 2> ਹੈ। (YY%, ਮਤਲਬ 100 ਵਿੱਚੋਂ YY) ਭੇਜਣ ਵਾਲਾ: ਖੇਤੀਬਾੜੀ ਅਤੇ ਕਿਸਾਨ ਭਲਾਈ ਮੰਤਰਾਲਾ

Sheet LS4
A1: eng | B1: hin | C1: mar | D1: odi | E1: ben | F1: tel | G1: kan | H1: pun
A2: New weather information for farmers: <SMS Date> <SMS Month> 2025 In your locality, before <Date AA> <Month B>, the possibility of a continuous rainy season arriving is <qual 1>. (XX%, meaning XX in 100) | B2: किसानों के लिए नई मौसम जानकारी: <SMS Date> <SMS Month> 2025 आपके इलाके में, <Date AA> <Month B> के पहले, लगतार बारिश का मौसम आने की <qual 1> संभावना है| (XX% यानी 100 में से XX) | C2: शेतकऱ्यांसाठी नवी हवामान माहिती – <SMS Date> <SMS Month> 2025 तुमच्या भागात <Date AA> <Month B> पूर्वी सलग पावसाळा सुरू होण्याची शक्यता <qual 1> आहे. (XX%, म्हणजे 100 पैकी XX) | D2: ଚାଷୀଙ୍କ ପାଇଁ ନୂତନ ପାଣିପାଗ ସୂଚନା: <SMS Date> <SMS Month> 2025 ଆପଣଙ୍କ ଅଞ୍ଚଳରେ, <Date AA> <Month B> ପୂର୍ବରୁ, ଏକ ଲଗାତର ବର୍ଷା ଋତୁ ଆସିବାର ସମ୍ଭାବନା <qual 1> ଅଟେ। (XX%, ଅର୍ଥାତ୍ 100 ରେ XX) | E2: কৃষকদের জন্য নতুন আবহাওয়ার তথ্য: <SMS Date> <SMS Month> 2025 আপনার এলাকায়, <Date AA> <Month B> এর আগে, একটানা বর্ষা আসার <qual 1> সম্ভাবনা। (XX%, অর্থাৎ 100-এর মধ্যে XX) | F2: రైతుల కోసం తాజా వాతావరణ సమాచారం: <SMS Date> <SMS Month> 2025 మీ ప్రాంతం లో, <Date AA> <Month B> ముందు, నిరంతర వర్షాలు వచ్చేందుకు <qual 1> అవకాశం ఉంది. (XX%, అంటే, 100 లో XX) | G2: ರೈತರಿಗೆ ಹೊಸ ಹವಾಮಾನ ಮಾಹಿತಿ: <SMS Date> <SMS Month> 2025 ನಿಮ್ಮ ಪ್ರದೇಶದಲ್ಲಿ, <Date AA> <Month B> ಗಿಂತ ಮುಂಚೆ, ನಿರಂತರ ಮಳೆ ಬರುವ ಸಾಧ್ಯತೆ <qual 1>. (XX%, ಅಂದರೆ 100 ರಲ್ಲಿ XX) | H2: ਕਿਸਾਨਾਂ ਲਈ ਨਵਾਂ ਮੌਸਮ ਜਾਣਕਾਰੀ: <SMS Date> <SMS Month> 2025 ਤੁਹਾਡੇ ਇਲਾਕੇ ਵਿੱਚ, <Date AA> <Month B> ਤੋਂ ਪਹਿਲਾਂ, ਲਗਾਤਾਰ ਵਰਖਾ ਦੇ ਮੌਸਮ ਦੇ ਆਉਣ ਦੀ ਸੰਭਾਵਨਾ <qual 1> ਹੈ। (XX%, ਮਤਲਬ 100 ਵਿੱਚੋਂ XX)

Sheet LS1_IVRS
A1: eng | B1: odi
A2: This is new weather forecast information for farmers from Krushi Samruddhi, about [emphasize] when the rainy season is likely to arrive for your locality. This message was recorded on <SMS Date> <SMS Month> 2025 In your locality, the possibility of a continuous rainy season arriving is [emphasize] MOST LIKELY between <Date AA> <Month B> and <Date CC> <Month D>. There is a [emphasize] XX% chance that this estimate will be correct. The possibility of a continuous rainy season arriving before <Date AA> <Month B> is [emphasize] <qual 1> at around YY%. The possibility of a continuous rainy season arriving after <Date CC> <Month D>, is also [emphasize] <qual 2> at around ZZ%. Again, continuous rains will [emphasize] MOST LIKELY arrive between <Date AA> <Month B> and <Date CC> <Month D> in your locality. There is a [emphasize] XX% chance that this forecast will be correct. Remember, the continuous rainy season doesn’t just mean the first rain—it means the steady, farming-friendly rainfall. We will call you with an upDate on Thursday or Friday. If you have any questions, please call 155-333 for more information. | B2: ଏହା କୃଷି ସମୃଦ୍ଧିର ଚାଷୀଙ୍କ ପାଇଁ ନୂତନ ପାଣିପାଗ ପୂର୍ବାନୁମାନ ସୂଚନା, ଆପଣଙ୍କ ଅଞ୍ଚଳରେ ବର୍ଷା ଋତୁ ଆସିବାର ସମ୍ଭାବନା ଥିବା ବିଷୟରେ [ଗୁରୁତ୍ୱ ଦିଅନ୍ତୁ]। ଏହି ସୂଚନାଟି <SMS Date> <SMS Month> 2025 ରେ ପ୍ରସ୍ତୁତ କରାଯାଇଥିଲା। ଆପଣଙ୍କ ଅଞ୍ଚଳରେ, ଲଗାତାର ମୌସୁମୀ ବର୍ଷା ଆସିବାର ସମ୍ଭାବନା [ଗୁରୁତ୍ୱ ଦିଅନ୍ତୁ] <Date AA> <Month B> ଏବଂ <Date CC> <Month D> ମଧ୍ୟରେ ସବୁଠାରୁ ସର୍ବାଧିକ। ଏହି ଆକଳନ ସଠିକ୍ ହେବାର [ଗୁରୁତ୍ୱ ଦିଅନ୍ତୁ] XX% ସମ୍ଭାବନା ଅଛି। <Date AA> <Month B> ପୂର୍ବରୁ ଲଗାତାର ମୌସୁମୀ ବର୍ଷା ଆସିବାର ସମ୍ଭାବନା ପ୍ରାୟ YY% ରେ [ଗୁରୁତ୍ୱ ଦିଅନ୍ତୁ] ଯାହାକି <qual 1> । <Date CC> <Month D> ପରେ ଲଗାତାର ବର୍ଷା ଋତୁ ଆସିବାର ସମ୍ଭାବନା ପ୍ରାୟ ZZ% ରେ <qual 2> ଧରଣର । ପୁନର୍ବାର,ଆପଣଙ୍କ ଅଞ୍ଚଳରେ <Date AA> <Month B> ଏବଂ <Date CC> <Month D> ମଧ୍ୟରେ ଲଗାତାର ମୌସୁମୀ ବର୍ଷା ହେବାର ସମ୍ଭାବନା ସର୍ବାଧିକ । ଏହି ପୂର୍ବାନୁମାନ ସଠିକ ହେବାର [ଗୁରୁତ୍ୱ ଦିଅନ୍ତୁ] XX% ସମ୍ଭାବନା ଅଛି। ମନେରଖନ୍ତୁ, ଲଗାତାର ବର୍ଷା ଋତୁ କେବଳ ପ୍ରଥମ ବର୍ଷା ନୁହେଁ - ଏହାର ଅର୍ଥ ନିୟମିତ, କୃଷି-ଅନୁକୂଳ ବର୍ଷା। ଆମେ ଗୁରୁବାର କିମ୍ବା ଶୁକ୍ରବାର ଦିନ ଫୋନ କରି ଆପଣଙ୍କୁ ଅପଡେଟ ଜଣାଇବୁ । ଯଦି ଆପଣଙ୍କର କୌଣସି ପ୍ରଶ୍ନ ଅଛି, ତେବେ ଅଧିକ ସୂଚନା ପାଇଁ ଦୟାକରି 155-333 କୁ କଲ୍ କରନ୍ତୁ।

Sheet LS3_IVRS
A1: eng | B1: odi
A2: This is new weather forecast information for farmers from Krushi Samruddhi, about [emphasize] when the rainy season is likely to arrive for your locality. This message was recorded on <SMS Date> <SMS Month> 2025 In your locality, the continuous rainy season arriving is [emphasize] MOST LIKELY BEFORE <Date AA> <Month B>. There is a [emphasize] XX% chance that this estimate will be correct. Again, continuous rains will [emphasize] MOST LIKELY arrive BEFORE <Date AA> <Month B> in your locality. There is a [emphasize] XX% chance that this forecast will be correct. Remember, the continuous rainy season doesn’t just mean the first rain—it means the steady, farming-friendly rainfall. We will call you with an upDate on Thursday or Friday. If you have any questions, please call 155-333 for more information. | B2: ଏହା କୃଷି ସମୃଦ୍ଧିର ଚାଷୀଙ୍କ ପାଇଁ ନୂତନ ପାଣିପାଗ ପୂର୍ବାନୁମାନ ସୂଚନା, ଆପଣଙ୍କ ଅଞ୍ଚଳରେ ବର୍ଷା ଋତୁ କେବେ ଆସିବାର ସମ୍ଭାବନା ଅଛି ସେ ବିଷୟରେ [ଗୁରୁତ୍ୱ ଦିଅନ୍ତୁ]। ଏହି ସୂଚନାଟି <SMS Date> <SMS Month> 2025 ରେ ପ୍ରସ୍ତୁତ କରାଯାଇଥିଲା। ଆପଣଙ୍କ ଅଞ୍ଚଳରେ, ଲଗାତାର ବର୍ଷା ଋତୁ [ଗୁରୁତ୍ୱ ଦିଅନ୍ତୁ] <Date AA> <Month B> ପୂର୍ବରୁ ଆସିବାର ସର୍ବାଧିକ ସମ୍ଭାବନା ଅଛି। ଏହି ଆକଳନ ସଠିକ୍ ହେବାର [ଗୁରୁତ୍ୱ ଦିଅନ୍ତୁ] XX% ସମ୍ଭାବନା ଅଛି। ପୁନର୍ବାର, ଆପଣଙ୍କ ଅଞ୍ଚଳରେ ଲଗାତାର ମୌସୁମୀ ବର୍ଷା <Date AA> <Month B> ପୂର୍ବରୁ ହେବାର ସର୍ବାଧିକ ସମ୍ଭାବନା ଅଛି। ଏହି ପୂର୍ବାନୁମାନ ସଠିକ ହେବାର [ଗୁରୁତ୍ୱ ଦିଅନ୍ତୁ] XX% ସମ୍ଭାବନା ଅଛି। ମନେରଖନ୍ତୁ, ଲଗାତାର ବର୍ଷା ଋତୁ କେବଳ ପ୍ରଥମ ବର୍ଷା ନୁହେଁ - ଏହାର ଅର୍ଥ ନିୟମିତ, କୃଷି-ଅନୁକୂଳ ବର୍ଷା। ଆମେ ଗୁରୁବାର କିମ୍ବା ଶୁକ୍ରବାର ଦିନ ଫୋନ କରି ଆପଣଙ୍କୁ ଅପଡେଟ ଜଣାଇବୁ । ଯଦି ଆପଣଙ୍କର କୌଣସି ପ୍ରଶ୍ନ ଅଛି, ତେବେ ଅଧିକ ସୂଚନା ପାଇଁ ଦୟାକରି 155-333 କୁ କଲ୍ କରନ୍ତୁ।

Sheet OC1
A1: eng | B1: hin | C1: mar | D1: odi | E1: ben | F1: tel | G1: kan | H1: pun
A2: New weather information for farmers: <SMS Date> <SMS Month> 2025 In your locality, the continuous rainy season has started. Till <Date AA> <Month B>, the possibility of persistent continuous rain is <qual 1>. (XX%, meaning XX in 100) Before <Date AA> <Month B>, the possibility of a dry spell is <qual 2>. (YY%, meaning YY in 100) Sender: Ministry of Agriculture and Farmers’ Welfare | B2: किसानों के लिए नई मौसम जानकारी: <SMS Date> <SMS Month> 2025 आपके इलाके में, लगतार बारिश का मौसम शुरू हो गया है| <Date AA> <Month B> तक, लगातार बारिश जारी रहने की <qual 1> संभावना है| (XX% यानी 100 में से XX) <Date AA> <Month B> के पहले, सूखा पडने की <qual 2> संभावना है| (YY% यानी 100 में से YY) प्रेषक: कृषि एवं किसान कल्याण मंत्रालय | C2: शेतकऱ्यांसाठी नवी हवामान माहिती – <SMS Date> <SMS Month> 2025 तुमच्या भागात सलग पावसाळा सुरू झाला आहे. <Date AA> <Month B> पर्यंत सलग पाऊस चालू राहण्याची शक्यता <qual 1> आहे. (XX%, म्हणजे 100 पैकी XX) <Date AA> <Month B> पूर्वी कोरडे पडण्याची शक्यता <qual 2> आहे. (YY%, म्हणजे 100 पैकी YY) प्रेषक: कृषी आणि शेतकरी कल्याण मंत्रालय | D2: ଚାଷୀଙ୍କ ପାଇଁ ନୂତନ ପାଣିପାଗ ସୂଚନା: <SMS Date> <SMS Month> 2025 ଆପଣଙ୍କ ଅଞ୍ଚଳରେ, ଲଗାତର ବର୍ଷା ଋତୁ ଆରମ୍ଭ ହୋଇଗଲାଣି। <Date AA> <Month B> ପର୍ଯ୍ୟନ୍ତ, ଲଗାତର ବର୍ଷାର ସମ୍ଭାବନା < qual 1 > ଅଟେ। (XX%, ଅର୍ଥାତ୍ 100 ରେ XX) <Date AA> <Month B> ପୂର୍ବରୁ, ପାଗ ଶୁଖିଲା ରହିବା ର ସମ୍ଭାବନା <qual 2> ଅଟେ। (YY%, ଅର୍ଥାତ୍ 100 ରେ YY) ପ୍ରେରକ: କୃଷି ଏବଂ କୃଷକ କଲ୍ୟାଣ ମନ୍ତ୍ରଣାଳୟ | E2: কৃষকদের জন্য নতুন আবহাওয়ার তথ্য: <SMS Date> <SMS Month> 2025. আপনার এলাকায়, একটানা বর্ষা শুরু হয়েছে। <Date AA> <Month B> পর্যন্ত, একটানা বৃষ্টিপাতের <qual 1> সম্ভাবনা । (XX%, অর্থাৎ 100-এর মধ্যে XX) <Date AA> <Month B> এর আগে, শুষ্ক আবহাওয়ার <qual 2> সম্ভাবনা । (YY%, অর্থাৎ 1০০-এর মধ্যে YY) কৃষি ও কৃষক কল্যাণ মন্ত্রণালয়” দ্বারা প্রচারিত । | F2: రైతుల కోసం తాజా వాతావరణ సమాచారం: <SMS Date> <SMS Month> 2025 మీ ప్రాంతంలో, నిరంతర వర్షాలు ప్రారంభమయ్యాయి. <Date AA> <Month B> వరకు, నిరంతర వర్షపాతం ఉండేందుకు <qual 1> అవకాశం ఉంది. (XX%, అంటే, 100 లో XX) <Date AA> <Month B> ముందు, పొడి వాతావరణం ఉండేందుకు <qual 2> అవకాశం ఉంది. (YY%, అంటే, 100 లో YY) పంపిస్తున్నది: వ్యవసాయ మరియు రైతు సంక్షేమ మంత్రిత్వ శాఖ | G2: ರೈತರಿಗೆ ಹೊಸ ಹವಾಮಾನ ಮಾಹಿತಿ: <SMS Date> <SMS Month> 2025 ನಿಮ್ಮ ಪ್ರದೇಶದಲ್ಲಿ, ನಿರಂತರ ಮಳೆಗಾಲ ಪ್ರಾರಂಭವಾಗಿದೆ. <Date AA> <Month B> ರವರೆಗೆ, ನಿರಂತರ ಮಳೆಯ ಸಾಧ್ಯತೆ <qual 1>. (XX%, ಅಂದರೆ 100 ರಲ್ಲಿ XX) <Date AA> <Month B> ಕ್ಕಿಂತ ಮೊದಲು, ಒಣಹವೆ ಸಾಧ್ಯತೆಯು <qual 2>. (YY%, ಅಂದರೆ 100 ರಲ್ಲಿ YY) ಪ್ರಾಯೋಜಕರು: ಕೃಷಿ ಮತ್ತು ರೈತರ ಕಲ್ಯಾಣ ಸಚಿವಾಲಯ" | H2: ਕਿਸਾਨਾਂ ਲਈ ਨਵੀਂ ਮੌਸਮ ਜਾਣਕਾਰੀ: <SMS Date> <SMS Month> 2025 ਤੁਹਾਡੇ ਇਲਾਕੇ ਵਿੱਚ ਲਗਾਤਾਰ ਮੀਂਹ ਦੇ ਮੌਸਮ ਦੀ ਸ਼ੁਰੂਆਤ ਹੋ ਚੁਕੀ ਹੈ। <Date AA> <Month B> ਤੱਕ, ਲਗਾਤਾਰ ਵਰਖਾ ਦੇ ਜਾਰੀ ਰਹਿਣ ਦੀ ਸੰਭਾਵਨਾ <qual 1> ਹੈ। (XX%, ਮਤਲਬ 100 ਵਿੱਚੋਂ XX) <Date AA> <Month B> ਤੋਂ ਪਹਿਲਾਂ, ਸੁੱਕੇ ਦੌਰ ਦੇ ਆਉਣ ਦੀ ਸੰਭਾਵਨਾ <qual 2> ਹੈ। (YY%, ਮਤਲਬ 100 ਵਿੱਚੋਂ YY) ਭੇਜਣ ਵਾਲਾ: ਖੇਤੀਬਾੜੀ ਅਤੇ ਕਿਸਾਨ ਭਲਾਈ ਮੰਤਰਾਲਾ

Sheet OC2
A1: eng | B1: hin | C1: mar | D1: odi | E1: ben | F1: tel | G1: kan | H1: pun
A2: New weather information for farmers: <SMS Date> <SMS Month> 2025 In your locality, the continuous rainy season has started. Till <Date AA> <Month B>, the possibility of persistent continuous rain is <qual 1>. (XX%, meaning XX in 100) | B2: किसानों के लिए नई मौसम जानकारी: <SMS Date> <SMS Month> 2025 आपके इलाके में, लगतार बारिश का मौसम शुरू हो गया है| <Date AA> <Month B> तक, लगातार बारिश जारी रहने की <qual 1> संभावना है| (XX% यानी 100 में से XX) | C2: शेतकऱ्यांसाठी नवी हवामान माहिती – <SMS Date> <SMS Month> 2025 तुमच्या भागात सलग पावसाळा सुरू झाला आहे. <Date AA> <Month B> पर्यंत सलग पाऊस चालू राहण्याची शक्यता <qual 1> आहे. (XX%, म्हणजे 100 पैकी XX) | D2: ଚାଷୀଙ୍କ ପାଇଁ ନୂତନ ପାଣିପାଗ ସୂଚନା: <SMS Date> <SMS Month> 2025 ଆପଣଙ୍କ ଅଞ୍ଚଳରେ, ଲଗାତର ବର୍ଷା ଋତୁ ଆରମ୍ଭ ହୋଇଗଲାଣି। <Date AA> <Month B> ପର୍ଯ୍ୟନ୍ତ, ଲଗାତର ବର୍ଷାର ସମ୍ଭାବନା < qual 1 > ଅଟେ। (XX%, ଅର୍ଥାତ୍ 100 ରେ XX) | E2: কৃষকদের জন্য নতুন আবহাওয়ার তথ্য: <SMS Date> <SMS Month> 2025. আপনার এলাকায়, একটানা বর্ষা শুরু হয়েছে। <Date AA> <Month B> পর্যন্ত, একটানা বৃষ্টিপাতের <qual 1> সম্ভাবনা । (XX%, অর্থাৎ 100-এর মধ্যে XX) | F2: రైతుల కోసం తాజా వాతావరణ సమాచారం: <SMS Date> <SMS Month> 2025 మీ ప్రాంతంలో, నిరంతర వర్షాలు ప్రారంభమయ్యాయి. <Date AA> <Month B> వరకు, నిరంతర వర్షపాతం ఉండేందుకు <qual 1> అవకాశం ఉంది. (XX%, అంటే, 100 లో XX) | G2: ರೈತರಿಗೆ ಹೊಸ ಹವಾಮಾನ ಮಾಹಿತಿ: <SMS Date> <SMS Month> 2025 ನಿಮ್ಮ ಪ್ರದೇಶದಲ್ಲಿ, ನಿರಂತರ ಮಳೆಗಾಲ ಪ್ರಾರಂಭವಾಗಿದೆ. <Date AA> <Month B> ರವರೆಗೆ, ನಿರಂತರ ಮಳೆಯ ಸಾಧ್ಯತೆ <qual 1> (XX%, ಅಂದರೆ 100 ರಲ್ಲಿ XX) | H2: ਕਿਸਾਨਾਂ ਲਈ ਨਵੀਂ ਮੌਸਮ ਜਾਣਕਾਰੀ: <SMS Date> <SMS Month> 2025 ਤੁਹਾਡੇ ਇਲਾਕੇ ਵਿੱਚ ਲਗਾਤਾਰ ਮੀਂਹ ਦੇ ਮੌਸਮ ਦੀ ਸ਼ੁਰੂਆਤ ਹੋ ਚੁਕੀ ਹੈ। <Date AA> <Month B> ਤੱਕ, ਲਗਾਤਾਰ ਵਰਖਾ ਦੇ ਜਾਰੀ ਰਹਿਣ ਦੀ ਸੰਭਾਵਨਾ <qual 1> ਹੈ। (XX%, ਮਤਲਬ 100 ਵਿੱਚੋਂ XX)

Sheet DS1
A1: eng | B1: hin | C1: mar | D1: odi | E1: ben | F1: tel | G1: kan | H1: pun
A2: New weather information for farmers: <SMS Date> <SMS Month> 2025 In your locality, till <Date AA> <Month B>, the possibility of rainfall is <qual 1>. After that, the possibility of at least a 10-day dry spell occurring is also <qual 2>. (XX%, meaning XX in 100) Sender: Ministry of Agriculture and Farmers’ Welfare | B2: किसानों के लिए नई मौसम जानकारी: <SMS Date> <SMS Month> 2025 आपके इलाके में, <Date AA> <Month B> तक, बारिश गिरने की <qual 1> संभावना है| उसके बाद, कम से कम 10 दिन का सूखा पडने की भी <qual 2> संभावना है| (XX% यानी 100 में से XX) प्रेषक: कृषि एवं किसान कल्याण मंत्रालय | C2: शेतकऱ्यांसाठी नवी हवामान माहिती – <SMS Date> <SMS Month> 2025 तुमच्या भागात <Date AA> <Month B> पर्यंत पाऊस पडण्याची शक्यता <qual 1> आहे त्यानंतर किमान 10 दिवस कोरडे पडण्याची शक्यता देखील <qual 2> आहे. (XX%, म्हणजे 100 पैकी XX) प्रेषक: कृषी आणि शेतकरी कल्याण मंत्रालय | D2: ଚାଷୀଙ୍କ ପାଇଁ ନୂତନ ପାଣିପାଗ ସୂଚନା: <SMS Date> <SMS Month> 2025 ଆପଣଙ୍କ ଅଞ୍ଚଳରେ, <Date AA> <Month B> ପର୍ଯ୍ୟନ୍ତ, ବର୍ଷାର ସମ୍ଭାବନା <qual 1> ରହିବ। ଏହା ପରେ, ଅତି କମରେ 10 ଦିନର ଶୁଖିଲା ପାଗ ହେବାର ସମ୍ଭାବନା <qual 2> ଧରଣର ଅଟେ । (XX%, ଅର୍ଥାତ୍ 100 ରେ XX) ପ୍ରେରକ: କୃଷି ଏବଂ କୃଷକ କଲ୍ୟାଣ ମନ୍ତ୍ରଣାଳୟ | E2: কৃষকদের জন্য নতুন আবহাওয়ার তথ্য: <SMS Date> <SMS Month> 2025. আপনার এলাকায়, <Date AA> <Month B> পর্যন্ত, বৃষ্টিপাতের <qual 1>সম্ভাবনা। এরপর, কমপক্ষে ১০ দিনের শুষ্ক আবহাওয়ার <qual 2> সম্ভাবনাও আছে। (XX%, অর্থাৎ 1০০-এর মধ্যে XX)। কৃষি ও কৃষক কল্যাণ মন্ত্রণালয়” দ্বারা প্রচারিত । | F2: రైతుల కోసం తాజా వాతావరణ సమాచారం: <SMS Date> <SMS Month> 2025 మీ ప్రాంతంలో, <Date AA> <Month B> వరకు, నిరంతర వర్షపాతం ఉండేందుకు <qual 1> అవకాశం ఉంది. ఆ తర్వాత, కనీసం 10 రోజులు పొడి వాతావరణం ఉండేందుకు <qual 2> అవకాశం ఉంది. (XX%, అంటే, 100 లో XX) పంపిస్తున్నది: వ్యవసాయ మరియు రైతు సంక్షేమ మంత్రిత్వ శాఖ | G2: ರೈತರಿಗೆ ಹೊಸ ಹವಾಮಾನ ಮಾಹಿತಿ: <SMS Date> <SMS Month> 2025 ನಿಮ್ಮ ಪ್ರದೇಶದಲ್ಲಿ,<Date AA> <Month B> ರವರೆಗೆ, ಮಳೆಯ ಸಾಧ್ಯತೆ <qual 1> ಅದರ ನಂತರ, ಕನಿಷ್ಠ 10 ದಿನಗಳ ಒಣ ಹವೆ ಸಂಭವಿಸುವ ಸಾಧ್ಯತೆಯೂ <qual 2> (XX%, ಅಂದರೆ 100 ರಲ್ಲಿ XX) ಪ್ರಾಯೋಜಕರು: ಕೃಷಿ ಮತ್ತು ರೈತರ ಕಲ್ಯಾಣ ಸಚಿವಾಲಯ | H2: ਕਿਸਾਨਾਂ ਲਈ ਨਵੀਂ ਮੌਸਮ ਜਾਣਕਾਰੀ: <SMS Date> <SMS Month> 2025 ਤੁਹਾਡੇ ਇਲਾਕੇ ਵਿੱਚ, <Date AA> <Month B> ਤੱਕ ਵਰਖਾ ਪੈਣ ਦੀ ਸੰਭਾਵਨਾ <qual 1> ਹੈ। ਉਸ ਤੋਂ ਬਾਅਦ, ਘੱਟੋ-ਘੱਟ 10 ਦਿਨਾਂ ਦਾ ਸੁੱਕਾ ਦੌਰ ਆਉਣ ਦੀ ਸੰਭਾਵਨਾ ਵੀ <qual 2> ਹੈ। (XX%, ਮਤਲਬ 100 ਵਿੱਚੋਂ XX) ਭੇਜਣ ਵਾਲਾ: ਖੇਤੀਬਾੜੀ ਅਤੇ ਕਿਸਾਨ ਭਲਾਈ ਮੰਤਰਾਲਾ

Sheet DS2
A1: eng | B1: hin | C1: mar | D1: odi | E1: ben | F1: tel | G1: kan | H1: pun
A2: New weather information for farmers: <SMS Date> <SMS Month> 2025 In your locality, till <Date AA> <Month B>, the possibility of rainfall is <qual 1>. After that, the possibility of at least a 10-day dry spell occurring is also <qual 2>. (XX%, meaning XX in 100) | B2: किसानों के लिए नई मौसम जानकारी: <SMS Date> <SMS Month> 2025 आपके इलाके में, <Date AA> <Month B> तक, बारिश गिरने की <qual 1> संभावना है| उसके बाद, कम से कम 10 दिन का सूखा पडने की भी <qual 2> संभावना है| (XX% यानी 100 में से XX) | C2: शेतकऱ्यांसाठी नवी हवामान माहिती – <SMS Date> <SMS Month> 2025 तुमच्या भागात <Date AA> <Month B> पर्यंत पाऊस पडण्याची शक्यता <qual 1> आहे त्यानंतर किमान 10 दिवस कोरडे पडण्याची शक्यता देखील <qual 2> आहे. (XX%, म्हणजे 100 पैकी XX) | D2: ଚାଷୀଙ୍କ ପାଇଁ ନୂତନ ପାଣିପାଗ ସୂଚନା: <SMS Date> <SMS Month> 2025 ଆପଣଙ୍କ ଅଞ୍ଚଳରେ, <Date AA> <Month B> ପର୍ଯ୍ୟନ୍ତ, ବର୍ଷାର ସମ୍ଭାବନା <qual 1> ରହିବ। ଏହା ପରେ, ଅତି କମରେ 10 ଦିନର ଶୁଖିଲା ପାଗ ହେବାର ସମ୍ଭାବନା <qual 2> ଧରଣର ଅଟେ । (XX%, ଅର୍ଥାତ୍ 100 ରେ XX) | E2: কৃষকদের জন্য নতুন আবহাওয়ার তথ্য: <SMS Date> <SMS Month> 2025. আপনার এলাকায়, <Date AA> <Month B> পর্যন্ত, বৃষ্টিপাতের <qual 1>সম্ভাবনা। এরপর, কমপক্ষে ১০ দিনের শুষ্ক আবহাওয়ার <qual 2> সম্ভাবনাও আছে। (XX%, অর্থাৎ 1০০-এর মধ্যে XX)। | F2: రైతుల కోసం తాజా వాతావరణ సమాచారం: <SMS Date> <SMS Month> 2025 మీ ప్రాంతంలో, <Date AA> <Month B> వరకు, నిరంతర వర్షపాతం ఉండేందుకు <qual 1> అవకాశం ఉంది. ఆ తర్వాత, కనీసం 10 రోజులు పొడి వాతావరణం ఉండేందుకు <qual 2> అవకాశం ఉంది. (XX%, అంటే, 100 లో XX) | G2: ರೈತರಿಗೆ ಹೊಸ ಹವಾಮಾನ ಮಾಹಿತಿ: <SMS Date> <SMS Month> 2025 ನಿಮ್ಮ ಪ್ರದೇಶದಲ್ಲಿ,<Date AA> <Month B> ರವರೆಗೆ, ಮಳೆಯ ಸಾಧ್ಯತೆ <qual 1> ಅದರ ನಂತರ, ಕನಿಷ್ಠ 10 ದಿನಗಳ ಒಣ ಹವೆ ಸಂಭವಿಸುವ ಸಾಧ್ಯತೆಯೂ <qual 2>. (XX%, ಅಂದರೆ 100 ರಲ್ಲಿ XX). | H2: ਕਿਸਾਨਾਂ ਲਈ ਨਵੀਂ ਮੌਸਮ ਜਾਣਕਾਰੀ: <SMS Date> <SMS Month> 2025 ਤੁਹਾਡੇ ਇਲਾਕੇ ਵਿੱਚ, <Date AA> <Month B> ਤੱਕ ਵਰਖਾ ਪੈਣ ਦੀ ਸੰਭਾਵਨਾ <qual 1> ਹੈ। ਉਸ ਤੋਂ ਬਾਅਦ, ਘੱਟੋ-ਘੱਟ 10 ਦਿਨਾਂ ਦਾ ਸੁੱਕਾ ਦੌਰ ਆਉਣ ਦੀ ਸੰਭਾਵਨਾ ਵੀ <qual 2> ਹੈ। (XX%, ਮਤਲਬ 100 ਵਿੱਚੋਂ XX)
